Workbook

Sheet L1
D1: Monday | E1: Tuesday | F1: Wednesday | G1: Thursday | H1: Friday | I1: Saturday | J1: Sunday | K1: Monday | L1: Tuesday | M1: Wednesday | N1: Thursday | O1: Friday | P1: Saturday | Q1: Sunday | R1: Monday | S1: Tuesday | T1: Wednesday | U1: Thursday | V1: Friday | W1: Saturday | X1: Sunday | Y1: Monday | Z1: Tuesday | AA1: Wednesday | AB1: Thursday | AC1: Friday | AD1: Saturday | AE1: Sunday | AF1: Monday | AG1: Tuesday | AH1: Wednesday | AI1: Thursday | AJ1: Friday
A2: Name | B2: Grade | C2: GGID | D2: 46265 | E2: 46266 | F2: 46267 | G2: 46268 | H2: 46269 | I2: 46270 | J2: 46271 | K2: 46272 | L2: 46273 | M2: 46274 | N2: 46275 | O2: 46276 | P2: 46277 | Q2: 46278 | R2: 46279 | S2: 46280 | T2: 46281 | U2: 46282 | V2: 46283 | W2: 46284 | X2: 46285 | Y2: 46286 | Z2: 46287 | AA2: 46288 | AB2: 46289 | AC2: 46290 | AD2: 46291 | AE2: 46292 | AF2: 46293 | AG2: 46294 | AH2: 46295 | AI2: 46268 | AJ2: 46269 | AL2: WFO | AM2: WFH | AP2: 0.29166667 | AQ2: 0.33333333 | AR2: 0.375 | AS2: 0.41666667 | AT2: 0.45833333 | AU2: 0.5 | AV2: 0.54166667 | AW2: 0.58333333 | AX2: 0.625 | AY2: 0.66666667 | AZ2: 0.70833333 | BA2: 0.75 | BB2: 0.79166667 | BC2: 0.83333333 | BD2: 0.875 | BE2: 0.91666667 | BF2: 0.95833333 | BH2: WD | BI2: OFF | BJ2: Annual | BK2: Public Holiday | BL2: Compensation
A3: Amr Abdelwahab | B3: L1 | C3: 1859559 | D3: 0.45833333 | E3: 0.29166667 | F3: 0.45833333 | G3: 0.45833333 | H3: 0.45833333 | I3: OFF | J3: OFF | K3: Annual | L3: 0.58333333 | M3: Annual | N3: 0.58333333 | O3: 0.29166667 | P3: OFF | Q3: OFF | R3: 0.45833333 | S3: 0.29166667 | T3: 0.29166667 | U3: 0.29166667 | V3: 0.375 | W3: OFF | X3: OFF | Y3: 0.58333333 | Z3: 0.29166667 | AA3: 0.29166667 | AB3: 0.29166667 | AC3: 0.29166667 | AD3: OFF | AE3: OFF | AF3: 0.58333333 | AG3: 0.58333333 | AH3: 0.45833333 | AL3: 5 | AM3: 16 | AP3: =COUNTIF($D3:$AJ3,AP$2) -> 9 | AQ3: =COUNTIF($D3:$AJ3,AQ$2) -> 0 | AR3: =COUNTIF($D3:$AJ3,AR$2) -> 1 | AS3: =COUNTIF($D3:$AJ3,AS$2) -> 0 | AT3: =COUNTIF($D3:$AJ3,AT$2) -> 6 | AU3: =COUNTIF($D3:$AJ3,AU$2) -> 0 | AV3: =COUNTIF($D3:$AJ3,AV$2) -> 0 | AW3: =COUNTIF($D3:$AJ3,AW$2) -> 5 | ... BF3: =COUNTIF($D3:$AJ3,BF$2) -> 0 | BH3: =SUM(AP3:BF3) -> 21 | BI3: =COUNTIF(D3:AJ3,$BI$2) -> 8 | BJ3: =COUNTIF(D3:AJ3,$BJ$2) -> 2 | BK3: =COUNTIF(D3:AJ3,$BK$2) -> 0 | BL3: =COUNTIF(D3:AJ3,$BL$2) -> 0
A4: Sarah Elmaasrawy | B4: L1 | C4: 30041021 | D4: Sick | E4: Sick | F4: Sick | G4: Sick | H4: 0.45833333 | I4: OFF | J4: OFF | K4: 0.375 | L4: 0.375 | M4: 0.375 | N4: Annual | O4: Annual | P4: OFF | Q4: OFF | R4: 0.29166667 | S4: 0.29166667 | T4: 0.29166667 | U4: 0.29166667 | V4: 0.58333333 | W4: OFF | X4: OFF | Y4: 0.58333333 | Z4: 0.58333333 | AA4: 0.58333333 | AB4: 0.58333333 | AC4: 0.58333333 | AD4: OFF | AE4: OFF | AF4: 0.45833333 | AG4: 0.45833333 | AH4: 0.45833333 | AL4: 5 | AM4: 16 | AP4: =COUNTIF($D4:$AJ4,AP$2) -> 4 | AQ4: =COUNTIF($D4:$AJ4,AQ$2) -> 0 | AR4: =COUNTIF($D4:$AJ4,AR$2) -> 3 | AS4: =COUNTIF($D4:$AJ4,AS$2) -> 0 | AT4: =COUNTIF($D4:$AJ4,AT$2) -> 4 | AU4: =COUNTIF($D4:$AJ4,AU$2) -> 0 | AV4: =COUNTIF($D4:$AJ4,AV$2) -> 0 | AW4: =COUNTIF($D4:$AJ4,AW$2) -> 6 | ... BF4: =COUNTIF($D4:$AJ4,BF$2) -> 0 | BH4: =SUM(AP4:BF4) -> 17 | BI4: =COUNTIF(D4:AJ4,$BI$2) -> 8 | BJ4: =COUNTIF(D4:AJ4,$BJ$2) -> 2 | BK4: =COUNTIF(D4:AJ4,$BK$2) -> 0 | BL4: =COUNTIF(D4:AJ4,$BL$2) -> 0
A5: Habiba Sebak | B5: L1 | C5: 30120618 | D5: 0.58333333 | E5: 0.58333333 | F5: 0.58333333 | G5: 0.58333333 | H5: 0.58333333 | I5: OFF | J5: OFF | K5: 0.29166667 | L5: 0.29166667 | M5: 0.58333333 | N5: 0.29166667 | O5: 0.58333333 | P5: OFF | Q5: OFF | R5: 0.375 | S5: Annual | T5: 0.375 | U5: 0.375 | V5: 0.58333333 | W5: OFF | X5: OFF | Y5: 0.45833333 | Z5: 0.45833333 | AA5: 0.45833333 | AB5: 0.45833333 | AC5: 0.45833333 | AD5: OFF | AE5: OFF | AF5: 0.58333333 | AG5: 0.58333333 | AH5: 0.58333333 | AL5: 5 | AM5: 16 | AP5: =COUNTIF($D5:$AJ5,AP$2) -> 3 | AQ5: =COUNTIF($D5:$AJ5,AQ$2) -> 0 | AR5: =COUNTIF($D5:$AJ5,AR$2) -> 3 | AS5: =COUNTIF($D5:$AJ5,AS$2) -> 0 | AT5: =COUNTIF($D5:$AJ5,AT$2) -> 5 | AU5: =COUNTIF($D5:$AJ5,AU$2) -> 0 | AV5: =COUNTIF($D5:$AJ5,AV$2) -> 0 | AW5: =COUNTIF($D5:$AJ5,AW$2) -> 11 | ... BF5: =COUNTIF($D5:$AJ5,BF$2) -> 0 | BH5: =SUM(AP5:BF5) -> 22 | BI5: =COUNTIF(D5:AJ5,$BI$2) -> 8 | BJ5: =COUNTIF(D5:AJ5,$BJ$2) -> 1 | BK5: =COUNTIF(D5:AJ5,$BK$2) -> 0 | BL5: =COUNTIF(D5:AJ5,$BL$2) -> 0
A6: Ahmed Habil | B6: L1 | C6: 30000369 | D6: 0.58333333 | E6: 0.58333333 | F6: 0.58333333 | G6: 0.58333333 | H6: 0.58333333 | I6: OFF | J6: OFF | K6: 0.29166667 | L6: 0.29166667 | M6: 0.29166667 | N6: 0.29166667 | O6: 0.29166667 | P6: OFF | Q6: OFF | R6: 0.29166667 | S6: 0.45833333 | T6: 0.45833333 | U6: 0.45833333 | V6: 0.45833333 | W6: OFF | X6: OFF | Y6: 0.29166667 | Z6: 0.58333333 | AA6: 0.58333333 | AB6: 0.58333333 | AC6: 0.58333333 | AD6: OFF | AE6: OFF | AF6: 0.375 | AG6: 0.375 | AH6: 0.375 | AL6: 5 | AM6: 16 | AP6: =COUNTIF($D6:$AJ6,AP$2) -> 7 | AQ6: =COUNTIF($D6:$AJ6,AQ$2) -> 0 | AR6: =COUNTIF($D6:$AJ6,AR$2) -> 3 | AS6: =COUNTIF($D6:$AJ6,AS$2) -> 0 | AT6: =COUNTIF($D6:$AJ6,AT$2) -> 4 | AU6: =COUNTIF($D6:$AJ6,AU$2) -> 0 | AV6: =COUNTIF($D6:$AJ6,AV$2) -> 0 | AW6: =COUNTIF($D6:$AJ6,AW$2) -> 9 | ... BF6: =COUNTIF($D6:$AJ6,BF$2) -> 0 | BH6: =SUM(AP6:BF6) -> 23 | BI6: =COUNTIF(D6:AJ6,$BI$2) -> 8 | BJ6: =COUNTIF(D6:AJ6,$BJ$2) -> 0 | BK6: =COUNTIF(D6:AJ6,$BK$2) -> 0 | BL6: =COUNTIF(D6:AJ6,$BL$2) -> 0
A7: Mohamed Halim | B7: L1 | C7: 1842168 | D7: 0.375 | E7: 0.375 | F7: Annual | G7: Annual | H7: Annual | I7: OFF | J7: OFF | K7: 0.58333333 | L7: 0.58333333 | M7: 0.58333333 | N7: 0.58333333 | O7: 0.58333333 | P7: OFF | Q7: OFF | R7: 0.45833333 | S7: 0.45833333 | T7: Sick | U7: Sick | V7: Sick | W7: OFF | X7: OFF | Y7: Sick | Z7: Sick | AA7: Sick | AB7: Sick | AC7: Sick | AD7: OFF | AE7: OFF | AF7: Sick | AG7: Sick | AH7: 0.58333333 | AL7: 5 | AM7: 16 | AP7: =COUNTIF($D7:$AJ7,AP$2) -> 0 | AQ7: =COUNTIF($D7:$AJ7,AQ$2) -> 0 | AR7: =COUNTIF($D7:$AJ7,AR$2) -> 2 | AS7: =COUNTIF($D7:$AJ7,AS$2) -> 0 | AT7: =COUNTIF($D7:$AJ7,AT$2) -> 2 | AU7: =COUNTIF($D7:$AJ7,AU$2) -> 0 | AV7: =COUNTIF($D7:$AJ7,AV$2) -> 0 | AW7: =COUNTIF($D7:$AJ7,AW$2) -> 6 | ... BF7: =COUNTIF($D7:$AJ7,BF$2) -> 0 | BH7: =SUM(AP7:BF7) -> 10 | BI7: =COUNTIF(D7:AJ7,$BI$2) -> 8 | BJ7: =COUNTIF(D7:AJ7,$BJ$2) -> 3 | BK7: =COUNTIF(D7:AJ7,$BK$2) -> 0 | BL7: =COUNTIF(D7:AJ7,$BL$2) -> 0
A8: Mohannad Ali | B8: L1 | C8: 30041020 | D8: 0.29166667 | E8: 0.29166667 | F8: 0.29166667 | G8: 0.29166667 | H8: 0.29166667 | I8: OFF | J8: OFF | K8: 0.45833333 | L8: 0.45833333 | M8: 0.45833333 | N8: 0.45833333 | O8: 0.45833333 | P8: OFF | Q8: OFF | R8: 0.58333333 | S8: 0.58333333 | T8: 0.58333333 | U8: 0.58333333 | V8: Annual | W8: OFF | X8: OFF | Y8: Compensation | Z8: Annual | AA8: Annual | AB8: Annual | AC8: Annual | AD8: OFF | AE8: OFF | AF8: 0.29166667 | AG8: 0.29166667 | AH8: 0.29166667 | AL8: 5 | AM8: 16 | AP8: =COUNTIF($D8:$AJ8,AP$2) -> 8 | AQ8: =COUNTIF($D8:$AJ8,AQ$2) -> 0 | AR8: =COUNTIF($D8:$AJ8,AR$2) -> 0 | AS8: =COUNTIF($D8:$AJ8,AS$2) -> 0 | AT8: =COUNTIF($D8:$AJ8,AT$2) -> 5 | AU8: =COUNTIF($D8:$AJ8,AU$2) -> 0 | AV8: =COUNTIF($D8:$AJ8,AV$2) -> 0 | AW8: =COUNTIF($D8:$AJ8,AW$2) -> 4 | ... BF8: =COUNTIF($D8:$AJ8,BF$2) -> 0 | BH8: =SUM(AP8:BF8) -> 17 | BI8: =COUNTIF(AG8:AJ8,$BI$2) -> 0 | BJ8: =COUNTIF(AG8:AJ8,$BJ$2) -> 0 | BK8: =COUNTIF(AG8:AJ8,$BK$2) -> 0 | BL8: =COUNTIF(AG8:AJ8,$BL$2) -> 0
A9: Sherine Khaled | B9: L1 | C9: 30118404 | D9: 0.29166667 | E9: 0.45833333 | F9: 0.29166667 | G9: 0.29166667 | H9: 0.29166667 | I9: OFF | J9: OFF | K9: 0.58333333 | L9: 0.45833333 | M9: 0.29166667 | N9: 0.45833333 | O9: 0.45833333 | P9: OFF | Q9: OFF | R9: 0.58333333 | S9: 0.58333333 | T9: 0.58333333 | U9: 0.58333333 | V9: 0.29166667 | W9: OFF | X9: OFF | Y9: 0.29166667 | Z9: 0.29166667 | AA9: 0.29166667 | AB9: 0.29166667 | AC9: 0.29166667 | AD9: OFF | AE9: OFF | AF9: 0.29166667 | AG9: 0.29166667 | AH9: 0.29166667 | AL9: 5 | AM9: 16 | AP9: =COUNTIF($D9:$AJ9,AP$2) -> 14 | AQ9: =COUNTIF($D9:$AJ9,AQ$2) -> 0 | AR9: =COUNTIF($D9:$AJ9,AR$2) -> 0 | AS9: =COUNTIF($D9:$AJ9,AS$2) -> 0 | AT9: =COUNTIF($D9:$AJ9,AT$2) -> 4 | AU9: =COUNTIF($D9:$AJ9,AU$2) -> 0 | AV9: =COUNTIF($D9:$AJ9,AV$2) -> 0 | AW9: =COUNTIF($D9:$AJ9,AW$2) -> 5 | ... BF9: =COUNTIF($D9:$AJ9,BF$2) -> 0 | BH9: =SUM(AP9:BF9) -> 23 | BI9: =COUNTIF(D9:AJ9,$BI$2) -> 8 | BJ9: =COUNTIF(D9:AJ9,$BJ$2) -> 0 | BK9: =COUNTIF(D9:AJ9,$BK$2) -> 0 | BL9: =COUNTIF(D9:AJ9,$BL$2) -> 0
W10: z | BH10: =SUM(AP10:BF10) -> 0 | BI10: =COUNTIF(D10:AJ10,$BI$2) -> 0 | BJ10: =COUNTIF(D10:AJ10,$BJ$2) -> 0 | BK10: =COUNTIF(D10:AJ10,$BK$2) -> 0 | BL10: =COUNTIF(D10:AJ10,$BL$2) -> 0
A12: Start | C12: End | D12: 46265 | E12: 46266 | F12: 46267 | G12: 46268 | H12: 46269 | I12: 46270 | J12: 46271 | K12: 46272 | L12: 46273 | M12: 46274 | N12: 46275 | O12: 46276 | P12: 46277 | Q12: 46278 | R12: 46279 | S12: 46280 | T12: 46281 | U12: 46282 | V12: 46283 | W12: 46284 | X12: 46285 | Y12: 46286 | Z12: 46287 | AA12: 46288 | AB12: 46289 | AC12: 46290 | AD12: 46291 | AE12: 46292 | AF12: 46293 | AG12: 46294 | AH12: 46295
A13: 0.29166667 | C13: 0.66666667 | D13: =COUNTIF(D$3:D$10,$A13) -> 2 | E13: =COUNTIF(E$3:E$10,$A13) -> 2 | F13: =COUNTIF(F$3:F$10,$A13) -> 2 | G13: =COUNTIF(G$3:G$10,$A13) -> 2 | H13: =COUNTIF(H$3:H$10,$A13) -> 2 | I13: =COUNTIF(I$3:I$10,$A13) -> 0 | J13: =COUNTIF(J$3:J$10,$A13) -> 0 | K13: =COUNTIF(K$3:K$10,$A13) -> 2 | ... AF13: =COUNTIF(AF$3:AF$10,$A13) -> 2 | AG13: =COUNTIF(AG$3:AG$11,$A13) -> 2 | AH13: =COUNTIF(AH$3:AH$11,$A13) -> 2
A14: 0.33333333 | C14: 0.70833333 | D14: =COUNTIF(D$3:D$10,$A14) -> 0 | E14: =COUNTIF(E$3:E$10,$A14) -> 0 | F14: =COUNTIF(F$3:F$10,$A14) -> 0 | G14: =COUNTIF(G$3:G$10,$A14) -> 0 | H14: =COUNTIF(H$3:H$10,$A14) -> 0 | I14: =COUNTIF(I$3:I$10,$A14) -> 0 | J14: =COUNTIF(J$3:J$5,$A14) -> 0 | K14: =COUNTIF(K$3:K$5,$A14) -> 0 | L14: =COUNTIF(L$3:L$10,$A14) -> 0 | M14: =COUNTIF(M$3:M$10,$A14) -> 0 | N14: =COUNTIF(N$3:N$5,$A14) -> 0 | O14: =COUNTIF(O$3:O$5,$A14) -> 0 | P14: =COUNTIF(P$3:P$10,$A14) -> 0 | Q14: =COUNTIF(Q$3:Q$5,$A14) -> 0 | R14: =COUNTIF(R$3:R$5,$A14) -> 0 | S14: =COUNTIF(S$3:S$6,$A14) -> 0 | T14: =COUNTIF(T$3:T$10,$A14) -> 0 | U14: =COUNTIF(U$3:U$5,$A14) -> 0 | V14: =COUNTIF(V$3:V$5,$A14) -> 0 | W14: =COUNTIF(W$3:W$10,$A14) -> 0 | X14: =COUNTIF(X$3:X$5,$A14) -> 0 | Y14: =COUNTIF(Y$3:Y$5,$A14) -> 0 | Z14: =COUNTIF(Z$3:Z$9,$A14) -> 0 | AA14: =COUNTIF(AA$3:AA$10,$A14) -> 0 | AB14: =COUNTIF(AB$3:AB$10,$A14) -> 0 | AC14: =COUNTIF(AC$3:AC$5,$A14) -> 0 | AD14: =COUNTIF(AD$3:AD$10,$A14) -> 0 | AE14: =COUNTIF(AE$3:AE$5,$A14) -> 0 | AF14: =COUNTIF(AF$3:AF$5,$A14) -> 0 | AG14: =COUNTIF(AG$3:AG$11,$A14) -> 0 | AH14: =COUNTIF(AH$3:AH$11,$A14) -> 0
A15: 0.375 | C15: 0.75 | D15: =COUNTIF(D$3:D$10,$A15) -> 1 | E15: =COUNTIF(E$3:E$10,$A15) -> 1 | F15: =COUNTIF(F$3:F$10,$A15) -> 0 | G15: =COUNTIF(G$3:G$10,$A15) -> 0 | H15: =COUNTIF(H$3:H$10,$A15) -> 0 | I15: =COUNTIF(I$3:I$10,$A15) -> 0 | J15: =COUNTIF(J$3:J$5,$A15) -> 0 | K15: =COUNTIF(K$3:K$5,$A15) -> 1 | L15: =COUNTIF(L$3:L$10,$A15) -> 1 | M15: =COUNTIF(M$3:M$10,$A15) -> 1 | N15: =COUNTIF(N$3:N$5,$A15) -> 0 | O15: =COUNTIF(O$3:O$5,$A15) -> 0 | P15: =COUNTIF(P$3:P$10,$A15) -> 0 | Q15: =COUNTIF(Q$3:Q$5,$A15) -> 0 | R15: =COUNTIF(R$3:R$5,$A15) -> 1 | S15: =COUNTIF(S$3:S$6,$A15) -> 0 | T15: =COUNTIF(T$3:T$10,$A15) -> 1 | U15: =COUNTIF(U$3:U$5,$A15) -> 1 | V15: =COUNTIF(V$3:V$5,$A15) -> 1 | W15: =COUNTIF(W$3:W$10,$A15) -> 0 | X15: =COUNTIF(X$3:X$5,$A15) -> 0 | Y15: =COUNTIF(Y$3:Y$5,$A15) -> 0 | Z15: =COUNTIF(Z$3:Z$9,$A15) -> 0 | AA15: =COUNTIF(AA$3:AA$10,$A15) -> 0 | AB15: =COUNTIF(AB$3:AB$10,$A15) -> 0 | AC15: =COUNTIF(AC$3:AC$5,$A15) -> 0 | AD15: =COUNTIF(AD$3:AD$10,$A15) -> 0 | AE15: =COUNTIF(AE$3:AE$5,$A15) -> 0 | AF15: =COUNTIF(AF$3:AF$5,$A15) -> 0 | AG15: =COUNTIF(AG$3:AG$11,$A15) -> 1 | AH15: =COUNTIF(AH$3:AH$11,$A15) -> 1
A16: 0.41666667 | C16: 0.79166667 | D16: =COUNTIF(D$3:D$10,$A16) -> 0 | E16: =COUNTIF(E$3:E$10,$A16) -> 0 | F16: =COUNTIF(F$3:F$10,$A16) -> 0 | G16: =COUNTIF(G$3:G$10,$A16) -> 0 | H16: =COUNTIF(H$3:H$10,$A16) -> 0 | I16: =COUNTIF(I$3:I$10,$A16) -> 0 | J16: =COUNTIF(J$3:J$5,$A16) -> 0 | K16: =COUNTIF(K$3:K$5,$A16) -> 0 | L16: =COUNTIF(L$3:L$10,$A16) -> 0 | M16: =COUNTIF(M$3:M$10,$A16) -> 0 | N16: =COUNTIF(N$3:N$5,$A16) -> 0 | O16: =COUNTIF(O$3:O$5,$A16) -> 0 | P16: =COUNTIF(P$3:P$10,$A16) -> 0 | Q16: =COUNTIF(Q$3:Q$5,$A16) -> 0 | R16: =COUNTIF(R$3:R$5,$A16) -> 0 | S16: =COUNTIF(S$3:S$6,$A16) -> 0 | T16: =COUNTIF(T$3:T$10,$A16) -> 0 | U16: =COUNTIF(U$3:U$5,$A16) -> 0 | V16: =COUNTIF(V$3:V$5,$A16) -> 0 | W16: =COUNTIF(W$3:W$10,$A16) -> 0 | X16: =COUNTIF(X$3:X$5,$A16) -> 0 | Y16: =COUNTIF(Y$3:Y$5,$A16) -> 0 | Z16: =COUNTIF(Z$3:Z$9,$A16) -> 0 | AA16: =COUNTIF(AA$3:AA$10,$A16) -> 0 | AB16: =COUNTIF(AB$3:AB$10,$A16) -> 0 | AC16: =COUNTIF(AC$3:AC$5,$A16) -> 0 | AD16: =COUNTIF(AD$3:AD$10,$A16) -> 0 | AE16: =COUNTIF(AE$3:AE$5,$A16) -> 0 | AF16: =COUNTIF(AF$3:AF$5,$A16) -> 0 | AG16: =COUNTIF(AG$3:AG$11,$A16) -> 0 | AH16: =COUNTIF(AH$3:AH$11,$A16) -> 0
A17: 0.45833333 | C17: 0.83333333 | D17: =COUNTIF(D$3:D$10,$A17) -> 1 | E17: =COUNTIF(E$3:E$10,$A17) -> 1 | F17: =COUNTIF(F$3:F$10,$A17) -> 1 | G17: =COUNTIF(G$3:G$10,$A17) -> 1 | H17: =COUNTIF(H$3:H$10,$A17) -> 2 | I17: =COUNTIF(I$3:I$10,$A17) -> 0 | J17: =COUNTIF(J$3:J$5,$A17) -> 0 | K17: =COUNTIF(K$3:K$5,$A17) -> 0 | L17: =COUNTIF(L$3:L$10,$A17) -> 2 | M17: =COUNTIF(M$3:M$10,$A17) -> 1 | N17: =COUNTIF(N$3:N$5,$A17) -> 0 | O17: =COUNTIF(O$3:O$5,$A17) -> 0 | P17: =COUNTIF(P$3:P$10,$A17) -> 0 | Q17: =COUNTIF(Q$3:Q$5,$A17) -> 0 | R17: =COUNTIF(R$3:R$5,$A17) -> 1 | S17: =COUNTIF(S$3:S$6,$A17) -> 1 | T17: =COUNTIF(T$3:T$10,$A17) -> 1 | U17: =COUNTIF(U$3:U$5,$A17) -> 0 | V17: =COUNTIF(V$3:V$5,$A17) -> 0 | W17: =COUNTIF(W$3:W$10,$A17) -> 0 | X17: =COUNTIF(X$3:X$5,$A17) -> 0 | Y17: =COUNTIF(Y$3:Y$5,$A17) -> 1 | Z17: =COUNTIF(Z$3:Z$9,$A17) -> 1 | AA17: =COUNTIF(AA$3:AA$10,$A17) -> 1 | AB17: =COUNTIF(AB$3:AB$10,$A17) -> 1 | AC17: =COUNTIF(AC$3:AC$5,$A17) -> 1 | AD17: =COUNTIF(AD$3:AD$10,$A17) -> 0 | AE17: =COUNTIF(AE$3:AE$5,$A17) -> 0 | AF17: =COUNTIF(AF$3:AF$5,$A17) -> 1 | AG17: =COUNTIF(AG$3:AG$11,$A17) -> 1 | AH17: =COUNTIF(AH$3:AH$11,$A17) -> 2
A18: 0.5 | C18: 0.875 | D18: =COUNTIF(D$3:D$10,$A18) -> 0 | E18: =COUNTIF(E$3:E$10,$A18) -> 0 | F18: =COUNTIF(F$3:F$10,$A18) -> 0 | G18: =COUNTIF(G$3:G$10,$A18) -> 0 | H18: =COUNTIF(H$3:H$10,$A18) -> 0 | I18: =COUNTIF(I$3:I$10,$A18) -> 0 | J18: =COUNTIF(J$3:J$5,$A18) -> 0 | K18: =COUNTIF(K$3:K$5,$A18) -> 0 | L18: =COUNTIF(L$3:L$10,$A18) -> 0 | M18: =COUNTIF(M$3:M$10,$A18) -> 0 | N18: =COUNTIF(N$3:N$5,$A18) -> 0 | O18: =COUNTIF(O$3:O$5,$A18) -> 0 | P18: =COUNTIF(P$3:P$10,$A18) -> 0 | Q18: =COUNTIF(Q$3:Q$5,$A18) -> 0 | R18: =COUNTIF(R$3:R$5,$A18) -> 0 | S18: =COUNTIF(S$3:S$6,$A18) -> 0 | T18: =COUNTIF(T$3:T$10,$A18) -> 0 | U18: =COUNTIF(U$3:U$5,$A18) -> 0 | V18: =COUNTIF(V$3:V$5,$A18) -> 0 | W18: =COUNTIF(W$3:W$10,$A18) -> 0 | X18: =COUNTIF(X$3:X$5,$A18) -> 0 | Y18: =COUNTIF(Y$3:Y$5,$A18) -> 0 | Z18: =COUNTIF(Z$3:Z$9,$A18) -> 0 | AA18: =COUNTIF(AA$3:AA$10,$A18) -> 0 | AB18: =COUNTIF(AB$3:AB$10,$A18) -> 0 | AC18: =COUNTIF(AC$3:AC$5,$A18) -> 0 | AD18: =COUNTIF(AD$3:AD$10,$A18) -> 0 | AE18: =COUNTIF(AE$3:AE$5,$A18) -> 0 | AF18: =COUNTIF(AF$3:AF$5,$A18) -> 0 | AG18: =COUNTIF(AG$3:AG$11,$A18) -> 0 | AH18: =COUNTIF(AH$3:AH$11,$A18) -> 0
A19: 0.54166667 | C19: 0.91666667 | D19: =COUNTIF(D$3:D$10,$A19) -> 0 | E19: =COUNTIF(E$3:E$10,$A19) -> 0 | F19: =COUNTIF(F$3:F$10,$A19) -> 0 | G19: =COUNTIF(G$3:G$10,$A19) -> 0 | H19: =COUNTIF(H$3:H$10,$A19) -> 0 | I19: =COUNTIF(I$3:I$10,$A19) -> 0 | J19: =COUNTIF(J$3:J$5,$A19) -> 0 | K19: =COUNTIF(K$3:K$5,$A19) -> 0 | L19: =COUNTIF(L$3:L$10,$A19) -> 0 | M19: =COUNTIF(M$3:M$10,$A19) -> 0 | N19: =COUNTIF(N$3:N$5,$A19) -> 0 | O19: =COUNTIF(O$3:O$5,$A19) -> 0 | P19: =COUNTIF(P$3:P$10,$A19) -> 0 | Q19: =COUNTIF(Q$3:Q$5,$A19) -> 0 | R19: =COUNTIF(R$3:R$5,$A19) -> 0 | S19: =COUNTIF(S$3:S$6,$A19) -> 0 | T19: =COUNTIF(T$3:T$10,$A19) -> 0 | U19: =COUNTIF(U$3:U$5,$A19) -> 0 | V19: =COUNTIF(V$3:V$5,$A19) -> 0 | W19: =COUNTIF(W$3:W$10,$A19) -> 0 | X19: =COUNTIF(X$3:X$5,$A19) -> 0 | Y19: =COUNTIF(Y$3:Y$5,$A19) -> 0 | Z19: =COUNTIF(Z$3:Z$9,$A19) -> 0 | AA19: =COUNTIF(AA$3:AA$10,$A19) -> 0 | AB19: =COUNTIF(AB$3:AB$10,$A19) -> 0 | AC19: =COUNTIF(AC$3:AC$5,$A19) -> 0 | AD19: =COUNTIF(AD$3:AD$10,$A19) -> 0 | AE19: =COUNTIF(AE$3:AE$5,$A19) -> 0 | AF19: =COUNTIF(AF$3:AF$5,$A19) -> 0 | AG19: =COUNTIF(AG$3:AG$11,$A19) -> 0 | AH19: =COUNTIF(AH$3:AH$11,$A19) -> 0
A20: 0.58333333 | C20: 0.95833333 | D20: =COUNTIF(D$3:D$10,$A20) -> 2 | E20: =COUNTIF(E$3:E$5,$A20) -> 1 | F20: =COUNTIF(F$3:F$10,$A20) -> 2 | G20: =COUNTIF(G$3:G$10,$A20) -> 2 | H20: =COUNTIF(H$3:H$10,$A20) -> 2 | I20: =COUNTIF(I$3:I$10,$A20) -> 0 | J20: =COUNTIF(J$3:J$5,$A20) -> 0 | K20: =COUNTIF(K$3:K$5,$A20) -> 0 | L20: =COUNTIF(L$3:L$10,$A20) -> 2 | M20: =COUNTIF(M$3:M$10,$A20) -> 2 | N20: =COUNTIF(N$3:N$5,$A20) -> 1 | O20: =COUNTIF(O$3:O$5,$A20) -> 1 | P20: =COUNTIF(P$3:P$10,$A20) -> 0 | Q20: =COUNTIF(Q$3:Q$5,$A20) -> 0 | R20: =COUNTIF(R$3:R$5,$A20) -> 0 | S20: =COUNTIF(S$3:S$6,$A20) -> 0 | T20: =COUNTIF(T$3:T$10,$A20) -> 2 | U20: =COUNTIF(U$3:U$5,$A20) -> 0 | V20: =COUNTIF(V$3:V$5,$A20) -> 2 | W20: =COUNTIF(W$3:W$10,$A20) -> 0 | X20: =COUNTIF(X$3:X$5,$A20) -> 0 | Y20: =COUNTIF(Y$3:Y$5,$A20) -> 2 | Z20: =COUNTIF(Z$3:Z$9,$A20) -> 2 | AA20: =COUNTIF(AA$3:AA$10,$A20) -> 2 | AB20: =COUNTIF(AB$3:AB$10,$A20) -> 2 | AC20: =COUNTIF(AC$3:AC$5,$A20) -> 1 | AD20: =COUNTIF(AD$3:AD$10,$A20) -> 0 | AE20: =COUNTIF(AE$3:AE$5,$A20) -> 0 | AF20: =COUNTIF(AF$3:AF$5,$A20) -> 2 | AG20: =COUNTIF(AG$3:AG$11,$A20) -> 2 | AH20: =COUNTIF(AH$3:AH$11,$A20) -> 2
A21: 0.625 | C21: 1 | D21: =COUNTIF(D$3:D$5,$A21) -> 0 | E21: =COUNTIF(E$3:E$5,$A21) -> 0 | F21: =COUNTIF(F$3:F$5,$A21) -> 0 | G21: =COUNTIF(G$3:G$5,$A21) -> 0 | H21: =COUNTIF(H$3:H$5,$A21) -> 0 | I21: =COUNTIF(I$3:I$5,$A21) -> 0 | J21: =COUNTIF(J$3:J$5,$A21) -> 0 | K21: =COUNTIF(K$3:K$5,$A21) -> 0 | ... AA21: =COUNTIF(AA$3:AA$5,$A21) -> 0 | AB21: =COUNTIF(AB$3:AB$10,$A21) -> 0 | AC21: =COUNTIF(AC$3:AC$5,$A21) -> 0 | AD21: =COUNTIF(AD$3:AD$5,$A21) -> 0 | AE21: =COUNTIF(AE$3:AE$5,$A21) -> 0 | AF21: =COUNTIF(AF$3:AF$5,$A21) -> 0 | AG21: =COUNTIF(AG$3:AG$11,$A21) -> 0 | AH21: =COUNTIF(AH$3:AH$11,$A21) -> 0
A22: 0.66666667 | C22: 1.0416667 | D22: =COUNTIF(D$3:D$5,$A22) -> 0 | E22: =COUNTIF(E$3:E$5,$A22) -> 0 | F22: =COUNTIF(F$3:F$5,$A22) -> 0 | G22: =COUNTIF(G$3:G$5,$A22) -> 0 | H22: =COUNTIF(H$3:H$5,$A22) -> 0 | I22: =COUNTIF(I$3:I$5,$A22) -> 0 | J22: =COUNTIF(J$3:J$5,$A22) -> 0 | K22: =COUNTIF(K$3:K$5,$A22) -> 0 | ... AF22: =COUNTIF(AF$3:AF$5,$A22) -> 0 | AG22: =COUNTIF(AG$3:AG$11,$A22) -> 0 | AH22: =COUNTIF(AH$3:AH$11,$A22) -> 0
A23: 0.70833333 | C23: 1.0833333 | D23: =COUNTIF(D$3:D$5,$A23) -> 0 | E23: =COUNTIF(E$3:E$5,$A23) -> 0 | F23: =COUNTIF(F$3:F$5,$A23) -> 0 | G23: =COUNTIF(G$3:G$5,$A23) -> 0 | H23: =COUNTIF(H$3:H$5,$A23) -> 0 | I23: =COUNTIF(I$3:I$5,$A23) -> 0 | J23: =COUNTIF(J$3:J$5,$A23) -> 0 | K23: =COUNTIF(K$3:K$5,$A23) -> 0 | ... AF23: =COUNTIF(AF$3:AF$5,$A23) -> 0 | AG23: =COUNTIF(AG$3:AG$11,$A23) -> 0 | AH23: =COUNTIF(AH$3:AH$11,$A23) -> 0
A24: 0.75 | C24: 1.125 | D24: =COUNTIF(D$3:D$5,$A24) -> 0 | E24: =COUNTIF(E$3:E$5,$A24) -> 0 | F24: =COUNTIF(F$3:F$5,$A24) -> 0 | G24: =COUNTIF(G$3:G$5,$A24) -> 0 | H24: =COUNTIF(H$3:H$5,$A24) -> 0 | I24: =COUNTIF(I$3:I$5,$A24) -> 0 | J24: =COUNTIF(J$3:J$5,$A24) -> 0 | K24: =COUNTIF(K$3:K$5,$A24) -> 0 | ... AF24: =COUNTIF(AF$3:AF$5,$A24) -> 0 | AG24: =COUNTIF(AG$3:AG$11,$A24) -> 0 | AH24: =COUNTIF(AH$3:AH$11,$A24) -> 0
A25: 0.79166667 | C25: 1.1666667 | D25: =COUNTIF(D$3:D$5,$A25) -> 0 | E25: =COUNTIF(E$3:E$5,$A25) -> 0 | F25: =COUNTIF(F$3:F$5,$A25) -> 0 | G25: =COUNTIF(G$3:G$5,$A25) -> 0 | H25: =COUNTIF(H$3:H$5,$A25) -> 0 | I25: =COUNTIF(I$3:I$5,$A25) -> 0 | J25: =COUNTIF(J$3:J$5,$A25) -> 0 | K25: =COUNTIF(K$3:K$5,$A25) -> 0 | ... AF25: =COUNTIF(AF$3:AF$5,$A25) -> 0 | AG25: =COUNTIF(AG$3:AG$11,$A25) -> 0 | AH25: =COUNTIF(AH$3:AH$11,$A25) -> 0
A26: 0.83333333 | C26: 1.2083333 | D26: =COUNTIF(D$3:D$5,$A26) -> 0 | E26: =COUNTIF(E$3:E$5,$A26) -> 0 | F26: =COUNTIF(F$3:F$5,$A26) -> 0 | G26: =COUNTIF(G$3:G$5,$A26) -> 0 | H26: =COUNTIF(H$3:H$5,$A26) -> 0 | I26: =COUNTIF(I$3:I$5,$A26) -> 0 | J26: =COUNTIF(J$3:J$5,$A26) -> 0 | K26: =COUNTIF(K$3:K$5,$A26) -> 0 | ... AF26: =COUNTIF(AF$3:AF$5,$A26) -> 0 | AG26: =COUNTIF(AG$3:AG$11,$A26) -> 0 | AH26: =COUNTIF(AH$3:AH$11,$A26) -> 0
A27: 0.875 | C27: 1.25 | D27: =COUNTIF(D$3:D$5,$A27) -> 0 | E27: =COUNTIF(E$3:E$5,$A27) -> 0 | F27: =COUNTIF(F$3:F$5,$A27) -> 0 | G27: =COUNTIF(G$3:G$5,$A27) -> 0 | H27: =COUNTIF(H$3:H$5,$A27) -> 0 | I27: =COUNTIF(I$3:I$5,$A27) -> 0 | J27: =COUNTIF(J$3:J$5,$A27) -> 0 | K27: =COUNTIF(K$3:K$5,$A27) -> 0 | ... AF27: =COUNTIF(AF$3:AF$5,$A27) -> 0 | AG27: =COUNTIF(AG$3:AG$11,$A27) -> 0 | AH27: =COUNTIF(AH$3:AH$11,$A27) -> 0
A28: 0.91666667 | C28: 1.2916667 | D28: =COUNTIF(D$3:D$5,$A28) -> 0 | E28: =COUNTIF(E$3:E$5,$A28) -> 0 | F28: =COUNTIF(F$3:F$5,$A28) -> 0 | G28: =COUNTIF(G$3:G$5,$A28) -> 0 | H28: =COUNTIF(H$3:H$5,$A28) -> 0 | I28: =COUNTIF(I$3:I$5,$A28) -> 0 | J28: =COUNTIF(J$3:J$5,$A28) -> 0 | K28: =COUNTIF(K$3:K$5,$A28) -> 0 | ... AF28: =COUNTIF(AF$3:AF$5,$A28) -> 0 | AG28: =COUNTIF(AG$3:AG$11,$A28) -> 0 | AH28: =COUNTIF(AH$3:AH$11,$A28) -> 0
A29: 0.95833333 | C29: 1.3333333 | D29: =COUNTIF(D$3:D$5,$A29) -> 0 | E29: =COUNTIF(E$3:E$5,$A29) -> 0 | F29: =COUNTIF(F$3:F$5,$A29) -> 0 | G29: =COUNTIF(G$3:G$5,$A29) -> 0 | H29: =COUNTIF(H$3:H$5,$A29) -> 0 | I29: =COUNTIF(I$3:I$5,$A29) -> 0 | J29: =COUNTIF(J$3:J$5,$A29) -> 0 | K29: =COUNTIF(K$3:K$5,$A29) -> 0 | ... AF29: =COUNTIF(AF$3:AF$5,$A29) -> 0 | AG29: =COUNTIF(AG$3:AG$11,$A29) -> 0 | AH29: =COUNTIF(AH$3:AH$11,$A29) -> 0
A30: 1 | C30: 1.375 | D30: =COUNTIF(D$3:D$5,$A30) -> 0 | E30: =COUNTIF(E$3:E$5,$A30) -> 0 | F30: =COUNTIF(F$3:F$5,$A30) -> 0 | G30: =COUNTIF(G$3:G$5,$A30) -> 0 | H30: =COUNTIF(H$3:H$5,$A30) -> 0 | I30: =COUNTIF(I$3:I$5,$A30) -> 0 | J30: =COUNTIF(J$3:J$5,$A30) -> 0 | K30: =COUNTIF(K$3:K$5,$A30) -> 0 | ... AF30: =COUNTIF(AF$3:AF$5,$A30) -> 0 | AG30: =COUNTIF(AG$3:AG$11,$A30) -> 0 | AH30: =COUNTIF(AH$3:AH$11,$A30) -> 0
A31: 0.041666667 | C31: 1.4166667 | D31: =COUNTIF(D$3:D$5,$A31) -> 0 | E31: =COUNTIF(E$3:E$5,$A31) -> 0 | F31: =COUNTIF(F$3:F$5,$A31) -> 0 | G31: =COUNTIF(G$3:G$5,$A31) -> 0 | H31: =COUNTIF(H$3:H$5,$A31) -> 0 | I31: =COUNTIF(I$3:I$5,$A31) -> 0 | J31: =COUNTIF(J$3:J$5,$A31) -> 0 | K31: =COUNTIF(K$3:K$5,$A31) -> 0 | ... AF31: =COUNTIF(AF$3:AF$5,$A31) -> 0 | AG31: =COUNTIF(AG$3:AG$11,$A31) -> 0 | AH31: =COUNTIF(AH$3:AH$11,$A31) -> 0
A33: Meals
A34: Work from home
A35: Annual
A36: Public Holiday
A37: Training
A38: Sick
A39: Compensation
A40: New Joiners Fixed Shift
A41: Available Slot

Sheet L2
D1: Monday | E1: Tuesday | F1: Wednesday | G1: Thursday | H1: Friday | I1: Saturday | J1: Sunday | K1: Monday | L1: Tuesday | M1: Wednesday | N1: Thursday | O1: Friday | P1: Saturday | Q1: Sunday | R1: Monday | S1: Tuesday | T1: Wednesday | U1: Thursday | V1: Friday | W1: Saturday | X1: Sunday | Y1: Monday | Z1: Tuesday | AA1: Wednesday | AB1: Thursday | AC1: Friday | AD1: Saturday | AE1: Sunday | AF1: Monday | AG1: Tuesday | AH1: Wednesday
A2: Username | B2: Grade | C2: GGID | D2: 46265 | E2: 46266 | F2: 46267 | G2: 46268 | H2: 46269 | I2: 46270 | J2: 46271 | K2: 46272 | L2: 46273 | M2: 46274 | N2: 46275 | O2: 46276 | P2: 46277 | Q2: 46278 | R2: 46279 | S2: 46280 | T2: 46281 | U2: 46282 | V2: 46283 | W2: 46284 | X2: 46285 | Y2: 46286 | Z2: 46287 | AA2: 46288 | AB2: 46289 | AC2: 46290 | AD2: 46291 | AE2: 46292 | AF2: 46293 | AG2: 46294 | AH2: 46295 | AM2: 0.29166667 | AN2: 0.33333333 | AO2: 0.375 | AP2: 0.41666667 | AQ2: 0.45833333 | AR2: 0.5 | AS2: 0.54166667 | AT2: 0.58333333 | AU2: 0.625 | AV2: 0.66666667 | AW2: 0.70833333 | AX2: 0.75 | AY2: 0.79166667 | AZ2: 0.83333333 | BA2: 0.875 | BB2: 0.91666667 | BC2: 0.95833333 | BD2: 1 | BG2: WD | BH2: OFF | BI2: Annual | BJ2: Public Holiday | BK2: Compensation
A3: Mohamed Elezaby | B3: L2 | C3: 1847226 | D3: 0.33333333 | E3: 0.33333333 | F3: 0.33333333 | G3: 0.33333333 | H3: Compensation | I3: OFF | J3: OFF | K3: 0.41666667 | L3: 0.41666667 | M3: 0.41666667 | N3: 0.41666667 | O3: 0.41666667 | P3: OFF | Q3: OFF | R3: 0.33333333 | S3: 0.33333333 | T3: 0.33333333 | U3: 0.33333333 | V3: 0.33333333 | W3: OFF | X3: OFF | Y3: 0.41666667 | Z3: 0.41666667 | AA3: 0.41666667 | AB3: 0.41666667 | AC3: 0.41666667 | AD3: OFF | AE3: OFF | AF3: 0.33333333 | AG3: 0.33333333 | AH3: 0.33333333 | AM3: =COUNTIF($A3:$AG3,AM$2) -> 0 | AN3: =COUNTIF($A3:$AG3,AN$2) -> 11 | AO3: =COUNTIF($A3:$AG3,AO$2) -> 0 | AP3: =COUNTIF($A3:$AG3,AP$2) -> 10 | AQ3: =COUNTIF($A3:$AG3,AQ$2) -> 0 | AR3: =COUNTIF($A3:$AG3,AR$2) -> 0 | AS3: =COUNTIF($A3:$AG3,AS$2) -> 0 | AT3: =COUNTIF($A3:$AG3,AT$2) -> 0 | ... BD3: =COUNTIF($A3:$AG3,BD$2) -> 0 | BG3: =SUM(AM3:BE3) -> 21 | BH3: =COUNTIF(D3:AG3,$BH$2) -> 8 | BI3: =COUNTIF(D3:AL3,$BI$2) -> 0 | BJ3: =COUNTIF(D3:AG3,$BJ$2) -> 0 | BK3: =COUNTIF(D3:AG3,$BK$2) -> 1
A4: Mohamed Aly | B4: L2 | C4: 30001708 | D4: 0.58333333 | E4: 0.58333333 | F4: 0.58333333 | G4: 0.58333333 | H4: 0.58333333 | I4: OFF | J4: OFF | K4: 0.33333333 | L4: 0.33333333 | M4: 0.33333333 | N4: 0.33333333 | O4: 0.33333333 | P4: OFF | Q4: OFF | R4: 0.41666667 | S4: Sick | T4: Sick | U4: 0.41666667 | V4: 0.41666667 | W4: OFF | X4: OFF | Y4: 0.58333333 | Z4: 0.58333333 | AA4: 0.58333333 | AB4: 0.58333333 | AC4: 0.58333333 | AD4: OFF | AE4: OFF | AF4: 0.58333333 | AG4: 0.58333333 | AH4: 0.58333333 | AM4: =COUNTIF($A4:$AG4,AM$2) -> 0 | AN4: =COUNTIF($A4:$AG4,AN$2) -> 5 | AO4: =COUNTIF($A4:$AG4,AO$2) -> 0 | AP4: =COUNTIF($A4:$AG4,AP$2) -> 3 | AQ4: =COUNTIF($A4:$AG4,AQ$2) -> 0 | AR4: =COUNTIF($A4:$AG4,AR$2) -> 0 | AS4: =COUNTIF($A4:$AG4,AS$2) -> 0 | AT4: =COUNTIF($A4:$AG4,AT$2) -> 12 | ... BD4: =COUNTIF($A4:$AG4,BD$2) -> 0 | BG4: =SUM(AM4:BE4) -> 20 | BH4: =COUNTIF(D4:AG4,$BH$2) -> 8 | BI4: =COUNTIF(D4:AL4,$BI$2) -> 0 | BJ4: =COUNTIF(D4:AG4,$BJ$2) -> 0 | BK4: =COUNTIF(D4:AG4,$BK$2) -> 0
A5: Amr Elsherbiny | B5: L2 | C5: 30001414 | D5: Annual | E5: Annual | F5: Annual | G5: Annual | H5: Annual | I5: OFF | J5: OFF | K5: 0.58333333 | L5: 0.58333333 | M5: 0.58333333 | N5: 0.58333333 | O5: 0.58333333 | P5: OFF | Q5: OFF | R5: 0.58333333 | S5: 0.58333333 | T5: 0.58333333 | U5: 0.58333333 | V5: 0.58333333 | W5: OFF | X5: OFF | Y5: Annual | Z5: Annual | AA5: Annual | AB5: Annual | AC5: Annual | AD5: OFF | AE5: OFF | AF5: 0.41666667 | AG5: 0.41666667 | AH5: 0.41666667 | AM5: =COUNTIF($A5:$AG5,AM$2) -> 0 | AN5: =COUNTIF($A5:$AG5,AN$2) -> 0 | AO5: =COUNTIF($A5:$AG5,AO$2) -> 0 | AP5: =COUNTIF($A5:$AG5,AP$2) -> 2 | AQ5: =COUNTIF($A5:$AG5,AQ$2) -> 0 | AR5: =COUNTIF($A5:$AG5,AR$2) -> 0 | AS5: =COUNTIF($A5:$AG5,AS$2) -> 0 | AT5: =COUNTIF($A5:$AG5,AT$2) -> 10 | ... BD5: =COUNTIF($A5:$AG5,BD$2) -> 0 | BG5: =SUM(AM5:BE5) -> 12 | BH5: =COUNTIF(D5:AG5,$BH$2) -> 8 | BI5: =COUNTIF(D5:AL5,$BI$2) -> 10 | BJ5: =COUNTIF(D5:AG5,$BJ$2) -> 0 | BK5: =COUNTIF(D5:AG5,$BK$2) -> 0
A6: Fady Farid | B6: L2 | C6: 30002263 | D6: 0.41666667 | E6: 0.41666667 | F6: 0.41666667 | G6: 0.41666667 | H6: 0.33333333 | I6: OFF | J6: OFF | K6: 0.33333333 | L6: 0.33333333 | M6: 0.33333333 | N6: 0.33333333 | O6: 0.33333333 | P6: OFF | Q6: OFF | R6: 0.58333333 | S6: 0.58333333 | T6: 0.58333333 | U6: 0.58333333 | V6: 0.58333333 | W6: OFF | X6: OFF | Y6: 0.33333333 | Z6: 0.33333333 | AA6: 0.33333333 | AB6: 0.33333333 | AC6: 0.33333333 | AD6: OFF | AE6: OFF | AF6: 0.33333333 | AG6: 0.33333333 | AH6: 0.33333333 | AM6: =COUNTIF($A6:$AG6,AM$2) -> 0 | AN6: =COUNTIF($A6:$AG6,AN$2) -> 13 | AO6: =COUNTIF($A6:$AG6,AO$2) -> 0 | AP6: =COUNTIF($A6:$AG6,AP$2) -> 4 | AQ6: =COUNTIF($A6:$AG6,AQ$2) -> 0 | AR6: =COUNTIF($A6:$AG6,AR$2) -> 0 | AS6: =COUNTIF($A6:$AG6,AS$2) -> 0 | AT6: =COUNTIF($A6:$AG6,AT$2) -> 5 | ... BD6: =COUNTIF($A6:$AG6,BD$2) -> 0 | BG6: =SUM(AM6:BE6) -> 22 | BH6: =COUNTIF(D6:AG6,$BH$2) -> 8 | BI6: =COUNTIF(AH6:AL6,$BI$2) -> 0 | BJ6: =COUNTIF(D6:AG6,$BJ$2) -> 0 | BK6: =COUNTIF(D6:AG6,$BK$2) -> 0
A9: Start | C9: End | D9: 46265 | E9: 46266 | F9: 46267 | G9: 46268 | H9: 46269 | I9: 46270 | J9: 46271 | K9: 46272 | L9: 46273 | M9: 46274 | N9: 46275 | O9: 46276 | P9: 46277 | Q9: 46278 | R9: 46279 | S9: 46280 | T9: 46281 | U9: 46282 | V9: 46283 | W9: 46284 | X9: 46285 | Y9: 46286 | Z9: 46287 | AA9: 46288 | AB9: 46289 | AC9: 46290 | AD9: 46291 | AE9: 46292 | AF9: 46293 | AG9: 46294 | AH9: 46295 | AM9: WFO | AN9: WFH
A10: 0.29166667 | C10: 0.66666667 | D10: =COUNTIF(D$3:D$6,$A10) -> 0 | E10: =COUNTIF(E$3:E$6,$A10) -> 0 | F10: =COUNTIF(F$3:F$6,$A10) -> 0 | G10: =COUNTIF(G$3:G$6,$A10) -> 0 | H10: =COUNTIF(H$3:H$4,$A10) -> 0 | I10: =COUNTIF(I$3:I$4,$A10) -> 0 | J10: =COUNTIF(J$3:J$5,$A10) -> 0 | K10: =COUNTIF(K$3:K$5,$A10) -> 0 | L10: =COUNTIF(L$3:L$6,$A10) -> 0 | M10: =COUNTIF(M$3:M$5,$A10) -> 0 | N10: =COUNTIF(N$3:N$5,$A10) -> 0 | O10: =COUNTIF(O$3:O$5,$A10) -> 0 | P10: =COUNTIF(P$3:P$5,$A10) -> 0 | Q10: =COUNTIF(Q$3:Q$6,$A10) -> 0 | R10: =COUNTIF(R$4:R$6,$A10) -> 0 | S10: =COUNTIF(S$4:S$6,$A10) -> 0 | T10: =COUNTIF(T$4:T$6,$A10) -> 0 | U10: =COUNTIF(U$4:U$5,$A10) -> 0 | V10: =COUNTIF(V$3:V$6,$A10) -> 0 | W10: =COUNTIF(W$3:W$5,$A10) -> 0 | X10: =COUNTIF(X$3:X$5,$A10) -> 0 | Y10: =COUNTIF(Y$3:Y$5,$A10) -> 0 | Z10: =COUNTIF(Z$4:Z$5,$A10) -> 0 | AA10: =COUNTIF(AA$4:AA$6,$A10) -> 0 | AB10: =COUNTIF(AB$4:AB$6,$A10) -> 0 | AC10: =COUNTIF(AC$4:AC$6,$A10) -> 0 | AD10: =COUNTIF(AD$4:AD$6,$A10) -> 0 | AE10: =COUNTIF(AE$3:AE$6,$A10) -> 0 | AF10: =COUNTIF(AF$3:AF$6,$A10) -> 0 | AG10: =COUNTIF(AG$3:AG$6,$A10) -> 0 | AH10: =COUNTIF(AH$3:AH$6,$A10) -> 0 | AM10: 2 | AN10: 19
A11: 0.33333333 | C11: 0.70833333 | D11: =COUNTIF(D$3:D$6,$A11) -> 1 | E11: =COUNTIF(E$3:E$6,$A11) -> 1 | F11: =COUNTIF(F$3:F$6,$A11) -> 1 | G11: =COUNTIF(G$3:G$6,$A11) -> 1 | H11: =COUNTIF(H$3:H$4,$A11) -> 0 | I11: =COUNTIF(I$3:I$4,$A11) -> 0 | J11: =COUNTIF(J$3:J$5,$A11) -> 0 | K11: =COUNTIF(K$3:K$5,$A11) -> 1 | L11: =COUNTIF(L$3:L$6,$A11) -> 2 | M11: =COUNTIF(M$3:M$5,$A11) -> 1 | N11: =COUNTIF(N$3:N$5,$A11) -> 1 | O11: =COUNTIF(O$3:O$5,$A11) -> 1 | P11: =COUNTIF(P$3:P$5,$A11) -> 0 | Q11: =COUNTIF(Q$3:Q$6,$A11) -> 0 | R11: =COUNTIF(R$4:R$6,$A11) -> 0 | S11: =COUNTIF(S$4:S$6,$A11) -> 0 | T11: =COUNTIF(T$4:T$6,$A11) -> 0 | U11: =COUNTIF(U$4:U$5,$A11) -> 0 | V11: =COUNTIF(V$3:V$6,$A11) -> 1 | W11: =COUNTIF(W$3:W$5,$A11) -> 0 | X11: =COUNTIF(X$3:X$5,$A11) -> 0 | Y11: =COUNTIF(Y$3:Y$5,$A11) -> 0 | Z11: =COUNTIF(Z$4:Z$5,$A11) -> 0 | AA11: =COUNTIF(AA$4:AA$6,$A11) -> 1 | AB11: =COUNTIF(AB$4:AB$6,$A11) -> 1 | AC11: =COUNTIF(AC$4:AC$6,$A11) -> 1 | AD11: =COUNTIF(AD$4:AD$6,$A11) -> 0 | AE11: =COUNTIF(AE$3:AE$6,$A11) -> 0 | AF11: =COUNTIF(AF$3:AF$6,$A11) -> 2 | AG11: =COUNTIF(AG$3:AG$6,$A11) -> 2 | AH11: =COUNTIF(AH$3:AH$6,$A11) -> 2 | AM11: 3 | AN11: 18
A12: 0.375 | C12: 0.75 | D12: =COUNTIF(D$3:D$6,$A12) -> 0 | E12: =COUNTIF(E$3:E$6,$A12) -> 0 | F12: =COUNTIF(F$3:F$6,$A12) -> 0 | G12: =COUNTIF(G$3:G$6,$A12) -> 0 | H12: =COUNTIF(H$3:H$4,$A12) -> 0 | I12: =COUNTIF(I$3:I$4,$A12) -> 0 | J12: =COUNTIF(J$3:J$5,$A12) -> 0 | K12: =COUNTIF(K$3:K$5,$A12) -> 0 | L12: =COUNTIF(L$3:L$6,$A12) -> 0 | M12: =COUNTIF(M$3:M$5,$A12) -> 0 | N12: =COUNTIF(N$3:N$5,$A12) -> 0 | O12: =COUNTIF(O$3:O$5,$A12) -> 0 | P12: =COUNTIF(P$3:P$5,$A12) -> 0 | Q12: =COUNTIF(Q$3:Q$6,$A12) -> 0 | R12: =COUNTIF(R$4:R$6,$A12) -> 0 | S12: =COUNTIF(S$4:S$6,$A12) -> 0 | T12: =COUNTIF(T$4:T$6,$A12) -> 0 | U12: =COUNTIF(U$4:U$5,$A12) -> 0 | V12: =COUNTIF(V$3:V$6,$A12) -> 0 | W12: =COUNTIF(W$3:W$5,$A12) -> 0 | X12: =COUNTIF(X$3:X$5,$A12) -> 0 | Y12: =COUNTIF(Y$3:Y$5,$A12) -> 0 | Z12: =COUNTIF(Z$4:Z$5,$A12) -> 0 | AA12: =COUNTIF(AA$4:AA$6,$A12) -> 0 | AB12: =COUNTIF(AB$4:AB$6,$A12) -> 0 | AC12: =COUNTIF(AC$4:AC$6,$A12) -> 0 | AD12: =COUNTIF(AD$4:AD$6,$A12) -> 0 | AE12: =COUNTIF(AE$3:AE$6,$A12) -> 0 | AF12: =COUNTIF(AF$3:AF$6,$A12) -> 0 | AG12: =COUNTIF(AG$3:AG$6,$A12) -> 0 | AH12: =COUNTIF(AH$3:AH$6,$A12) -> 0 | AM12: 5 | AN12: 16
A13: 0.41666667 | C13: 0.79166667 | D13: =COUNTIF(D$3:D$6,$A13) -> 1 | E13: =COUNTIF(E$3:E$6,$A13) -> 1 | F13: =COUNTIF(F$3:F$6,$A13) -> 1 | G13: =COUNTIF(G$3:G$6,$A13) -> 1 | H13: =COUNTIF(H$3:H$4,$A13) -> 0 | I13: =COUNTIF(I$3:I$4,$A13) -> 0 | J13: =COUNTIF(J$3:J$5,$A13) -> 0 | K13: =COUNTIF(K$3:K$5,$A13) -> 1 | L13: =COUNTIF(L$3:L$6,$A13) -> 1 | M13: =COUNTIF(M$3:M$5,$A13) -> 1 | N13: =COUNTIF(N$3:N$5,$A13) -> 1 | O13: =COUNTIF(O$3:O$5,$A13) -> 1 | P13: =COUNTIF(P$3:P$5,$A13) -> 0 | Q13: =COUNTIF(Q$3:Q$6,$A13) -> 0 | R13: =COUNTIF(R$4:R$6,$A13) -> 1 | S13: =COUNTIF(S$4:S$6,$A13) -> 0 | T13: =COUNTIF(T$4:T$6,$A13) -> 0 | U13: =COUNTIF(U$4:U$5,$A13) -> 1 | V13: =COUNTIF(V$3:V$6,$A13) -> 1 | W13: =COUNTIF(W$3:W$5,$A13) -> 0 | X13: =COUNTIF(X$3:X$5,$A13) -> 0 | Y13: =COUNTIF(Y$3:Y$5,$A13) -> 1 | Z13: =COUNTIF(Z$4:Z$5,$A13) -> 0 | AA13: =COUNTIF(AA$4:AA$6,$A13) -> 0 | AB13: =COUNTIF(AB$4:AB$6,$A13) -> 0 | AC13: =COUNTIF(AC$4:AC$6,$A13) -> 0 | AD13: =COUNTIF(AD$4:AD$6,$A13) -> 0 | AE13: =COUNTIF(AE$3:AE$6,$A13) -> 0 | AF13: =COUNTIF(AF$3:AF$6,$A13) -> 1 | AG13: =COUNTIF(AG$3:AG$6,$A13) -> 1 | AH13: =COUNTIF(AH$3:AH$6,$A13) -> 1 | AM13: 11 | AN13: 10
A14: 0.45833333 | C14: 0.83333333 | D14: =COUNTIF(D$3:D$6,$A14) -> 0 | E14: =COUNTIF(E$3:E$6,$A14) -> 0 | F14: =COUNTIF(F$3:F$6,$A14) -> 0 | G14: =COUNTIF(G$3:G$6,$A14) -> 0 | H14: =COUNTIF(H$3:H$4,$A14) -> 0 | I14: =COUNTIF(I$3:I$4,$A14) -> 0 | J14: =COUNTIF(J$3:J$5,$A14) -> 0 | K14: =COUNTIF(K$3:K$5,$A14) -> 0 | L14: =COUNTIF(L$3:L$6,$A14) -> 0 | M14: =COUNTIF(M$3:M$5,$A14) -> 0 | N14: =COUNTIF(N$3:N$5,$A14) -> 0 | O14: =COUNTIF(O$3:O$5,$A14) -> 0 | P14: =COUNTIF(P$3:P$5,$A14) -> 0 | Q14: =COUNTIF(Q$3:Q$6,$A14) -> 0 | R14: =COUNTIF(R$4:R$6,$A14) -> 0 | S14: =COUNTIF(S$4:S$6,$A14) -> 0 | T14: =COUNTIF(T$4:T$6,$A14) -> 0 | U14: =COUNTIF(U$4:U$5,$A14) -> 0 | V14: =COUNTIF(V$3:V$6,$A14) -> 0 | W14: =COUNTIF(W$3:W$5,$A14) -> 0 | X14: =COUNTIF(X$3:X$5,$A14) -> 0 | Y14: =COUNTIF(Y$3:Y$5,$A14) -> 0 | Z14: =COUNTIF(Z$4:Z$5,$A14) -> 0 | AA14: =COUNTIF(AA$4:AA$6,$A14) -> 0 | AB14: =COUNTIF(AB$4:AB$6,$A14) -> 0 | AC14: =COUNTIF(AC$4:AC$6,$A14) -> 0 | AD14: =COUNTIF(AD$4:AD$6,$A14) -> 0 | AE14: =COUNTIF(AE$3:AE$6,$A14) -> 0 | AF14: =COUNTIF(AF$3:AF$6,$A14) -> 0 | AG14: =COUNTIF(AG$3:AG$6,$A14) -> 0 | AH14: =COUNTIF(AH$3:AH$6,$A14) -> 0 | AM14: 5 | AN14: 16
A15: 0.5 | C15: 0.875 | D15: =COUNTIF(D$3:D$6,$A15) -> 0 | E15: =COUNTIF(E$3:E$6,$A15) -> 0 | F15: =COUNTIF(F$3:F$6,$A15) -> 0 | G15: =COUNTIF(G$3:G$6,$A15) -> 0 | H15: =COUNTIF(H$3:H$4,$A15) -> 0 | I15: =COUNTIF(I$3:I$4,$A15) -> 0 | J15: =COUNTIF(J$3:J$5,$A15) -> 0 | K15: =COUNTIF(K$3:K$5,$A15) -> 0 | L15: =COUNTIF(L$3:L$6,$A15) -> 0 | M15: =COUNTIF(M$3:M$5,$A15) -> 0 | N15: =COUNTIF(N$3:N$5,$A15) -> 0 | O15: =COUNTIF(O$3:O$5,$A15) -> 0 | P15: =COUNTIF(P$3:P$5,$A15) -> 0 | Q15: =COUNTIF(Q$3:Q$6,$A15) -> 0 | R15: =COUNTIF(R$4:R$6,$A15) -> 0 | S15: =COUNTIF(S$4:S$6,$A15) -> 0 | T15: =COUNTIF(T$4:T$6,$A15) -> 0 | U15: =COUNTIF(U$4:U$5,$A15) -> 0 | V15: =COUNTIF(V$3:V$6,$A15) -> 0 | W15: =COUNTIF(W$3:W$5,$A15) -> 0 | X15: =COUNTIF(X$3:X$5,$A15) -> 0 | Y15: =COUNTIF(Y$3:Y$5,$A15) -> 0 | Z15: =COUNTIF(Z$4:Z$5,$A15) -> 0 | AA15: =COUNTIF(AA$4:AA$6,$A15) -> 0 | AB15: =COUNTIF(AB$4:AB$6,$A15) -> 0 | AC15: =COUNTIF(AC$4:AC$6,$A15) -> 0 | AD15: =COUNTIF(AD$4:AD$6,$A15) -> 0 | AE15: =COUNTIF(AE$3:AE$6,$A15) -> 0 | AF15: =COUNTIF(AF$3:AF$6,$A15) -> 0 | AG15: =COUNTIF(AG$3:AG$6,$A15) -> 0 | AH15: =COUNTIF(AH$3:AH$6,$A15) -> 0
A16: 0.54166667 | C16: 0.91666667 | D16: =COUNTIF(D$3:D$6,$A16) -> 0 | E16: =COUNTIF(E$3:E$6,$A16) -> 0 | F16: =COUNTIF(F$3:F$6,$A16) -> 0 | G16: =COUNTIF(G$3:G$6,$A16) -> 0 | H16: =COUNTIF(H$3:H$4,$A16) -> 0 | I16: =COUNTIF(I$3:I$4,$A16) -> 0 | J16: =COUNTIF(J$3:J$5,$A16) -> 0 | K16: =COUNTIF(K$3:K$5,$A16) -> 0 | L16: =COUNTIF(L$3:L$6,$A16) -> 0 | M16: =COUNTIF(M$3:M$5,$A16) -> 0 | N16: =COUNTIF(N$3:N$5,$A16) -> 0 | O16: =COUNTIF(O$3:O$5,$A16) -> 0 | P16: =COUNTIF(P$3:P$5,$A16) -> 0 | Q16: =COUNTIF(Q$3:Q$6,$A16) -> 0 | R16: =COUNTIF(R$4:R$6,$A16) -> 0 | S16: =COUNTIF(S$4:S$6,$A16) -> 0 | T16: =COUNTIF(T$4:T$6,$A16) -> 0 | U16: =COUNTIF(U$4:U$5,$A16) -> 0 | V16: =COUNTIF(V$3:V$6,$A16) -> 0 | W16: =COUNTIF(W$3:W$5,$A16) -> 0 | X16: =COUNTIF(X$3:X$5,$A16) -> 0 | Y16: =COUNTIF(Y$3:Y$5,$A16) -> 0 | Z16: =COUNTIF(Z$4:Z$5,$A16) -> 0 | AA16: =COUNTIF(AA$4:AA$6,$A16) -> 0 | AB16: =COUNTIF(AB$4:AB$6,$A16) -> 0 | AC16: =COUNTIF(AC$4:AC$6,$A16) -> 0 | AD16: =COUNTIF(AD$4:AD$6,$A16) -> 0 | AE16: =COUNTIF(AE$3:AE$6,$A16) -> 0 | AF16: =COUNTIF(AF$3:AF$6,$A16) -> 0 | AG16: =COUNTIF(AG$3:AG$6,$A16) -> 0 | AH16: =COUNTIF(AH$3:AH$6,$A16) -> 0
A17: 0.58333333 | C17: 0.95833333 | D17: =COUNTIF(D$3:D$6,$A17) -> 1 | E17: =COUNTIF(E$3:E$6,$A17) -> 1 | F17: =COUNTIF(F$3:F$6,$A17) -> 1 | G17: =COUNTIF(G$3:G$6,$A17) -> 1 | H17: =COUNTIF(H$3:H$4,$A17) -> 1 | I17: =COUNTIF(I$3:I$4,$A17) -> 0 | J17: =COUNTIF(J$3:J$5,$A17) -> 0 | K17: =COUNTIF(K$3:K$5,$A17) -> 1 | L17: =COUNTIF(L$3:L$6,$A17) -> 1 | M17: =COUNTIF(M$3:M$5,$A17) -> 1 | N17: =COUNTIF(N$3:N$5,$A17) -> 1 | O17: =COUNTIF(O$3:O$5,$A17) -> 1 | P17: =COUNTIF(P$3:P$5,$A17) -> 0 | Q17: =COUNTIF(Q$3:Q$6,$A17) -> 0 | R17: =COUNTIF(R$4:R$6,$A17) -> 2 | S17: =COUNTIF(S$4:S$6,$A17) -> 2 | T17: =COUNTIF(T$4:T$6,$A17) -> 2 | U17: =COUNTIF(U$4:U$5,$A17) -> 1 | V17: =COUNTIF(V$3:V$6,$A17) -> 2 | W17: =COUNTIF(W$3:W$5,$A17) -> 0 | X17: =COUNTIF(X$3:X$5,$A17) -> 0 | Y17: =COUNTIF(Y$3:Y$5,$A17) -> 1 | Z17: =COUNTIF(Z$4:Z$5,$A17) -> 1 | AA17: =COUNTIF(AA$4:AA$6,$A17) -> 1 | AB17: =COUNTIF(AB$4:AB$6,$A17) -> 1 | AC17: =COUNTIF(AC$4:AC$6,$A17) -> 1 | AD17: =COUNTIF(AD$4:AD$6,$A17) -> 0 | AE17: =COUNTIF(AE$3:AE$6,$A17) -> 0 | AF17: =COUNTIF(AF$3:AF$6,$A17) -> 1 | AG17: =COUNTIF(AG$3:AG$6,$A17) -> 1 | AH17: =COUNTIF(AH$3:AH$6,$A17) -> 1
A18: 0.625 | C18: 0 | D18: =COUNTIF(D$3:D$6,$A18) -> 0 | E18: =COUNTIF(E$3:E$6,$A18) -> 0 | F18: =COUNTIF(F$3:F$6,$A18) -> 0 | G18: =COUNTIF(G$3:G$6,$A18) -> 0 | H18: =COUNTIF(H$3:H$4,$A18) -> 0 | I18: =COUNTIF(I$3:I$4,$A18) -> 0 | J18: =COUNTIF(J$3:J$5,$A18) -> 0 | K18: =COUNTIF(K$3:K$5,$A18) -> 0 | L18: =COUNTIF(L$3:L$6,$A18) -> 0 | M18: =COUNTIF(M$3:M$5,$A18) -> 0 | N18: =COUNTIF(N$3:N$5,$A18) -> 0 | O18: =COUNTIF(O$3:O$5,$A18) -> 0 | P18: =COUNTIF(P$3:P$5,$A18) -> 0 | Q18: =COUNTIF(Q$3:Q$6,$A18) -> 0 | R18: =COUNTIF(R$4:R$6,$A18) -> 0 | S18: =COUNTIF(S$4:S$6,$A18) -> 0 | T18: =COUNTIF(T$4:T$6,$A18) -> 0 | U18: =COUNTIF(U$4:U$5,$A18) -> 0 | V18: =COUNTIF(V$3:V$6,$A18) -> 0 | W18: =COUNTIF(W$3:W$5,$A18) -> 0 | X18: =COUNTIF(X$3:X$5,$A18) -> 0 | Y18: =COUNTIF(Y$3:Y$5,$A18) -> 0 | Z18: =COUNTIF(Z$4:Z$5,$A18) -> 0 | AA18: =COUNTIF(AA$4:AA$6,$A18) -> 0 | AB18: =COUNTIF(AB$4:AB$6,$A18) -> 0 | AC18: =COUNTIF(AC$4:AC$6,$A18) -> 0 | AD18: =COUNTIF(AD$4:AD$6,$A18) -> 0 | AE18: =COUNTIF(AE$3:AE$6,$A18) -> 0 | AF18: =COUNTIF(AF$3:AF$6,$A18) -> 0 | AG18: =COUNTIF(AG$3:AG$6,$A18) -> 0 | AH18: =COUNTIF(AH$3:AH$6,$A18) -> 0
A19: 0.66666667 | C19: 0.041666667 | D19: =COUNTIF(D$3:D$6,$A19) -> 0 | E19: =COUNTIF(E$3:E$6,$A19) -> 0 | F19: =COUNTIF(F$3:F$6,$A19) -> 0 | G19: =COUNTIF(G$3:G$6,$A19) -> 0 | H19: =COUNTIF(H$3:H$4,$A19) -> 0 | I19: =COUNTIF(I$3:I$4,$A19) -> 0 | J19: =COUNTIF(J$3:J$5,$A19) -> 0 | K19: =COUNTIF(K$3:K$5,$A19) -> 0 | L19: =COUNTIF(L$3:L$6,$A19) -> 0 | M19: =COUNTIF(M$3:M$5,$A19) -> 0 | N19: =COUNTIF(N$3:N$5,$A19) -> 0 | O19: =COUNTIF(O$3:O$5,$A19) -> 0 | P19: =COUNTIF(P$3:P$5,$A19) -> 0 | Q19: =COUNTIF(Q$3:Q$6,$A19) -> 0 | R19: =COUNTIF(R$4:R$6,$A19) -> 0 | S19: =COUNTIF(S$4:S$6,$A19) -> 0 | T19: =COUNTIF(T$4:T$6,$A19) -> 0 | U19: =COUNTIF(U$4:U$5,$A19) -> 0 | V19: =COUNTIF(V$3:V$6,$A19) -> 0 | W19: =COUNTIF(W$3:W$5,$A19) -> 0 | X19: =COUNTIF(X$3:X$5,$A19) -> 0 | Y19: =COUNTIF(Y$3:Y$5,$A19) -> 0 | Z19: =COUNTIF(Z$4:Z$5,$A19) -> 0 | AA19: =COUNTIF(AA$4:AA$6,$A19) -> 0 | AB19: =COUNTIF(AB$4:AB$6,$A19) -> 0 | AC19: =COUNTIF(AC$4:AC$6,$A19) -> 0 | AD19: =COUNTIF(AD$4:AD$6,$A19) -> 0 | AE19: =COUNTIF(AE$3:AE$6,$A19) -> 0 | AF19: =COUNTIF(AF$3:AF$6,$A19) -> 0 | AG19: =COUNTIF(AG$3:AG$6,$A19) -> 0 | AH19: =COUNTIF(AH$3:AH$6,$A19) -> 0
A20: 0.70833333 | C20: 0.083333333 | D20: =COUNTIF(D$3:D$6,$A20) -> 0 | E20: =COUNTIF(E$3:E$6,$A20) -> 0 | F20: =COUNTIF(F$3:F$6,$A20) -> 0 | G20: =COUNTIF(G$3:G$6,$A20) -> 0 | H20: =COUNTIF(H$3:H$4,$A20) -> 0 | I20: =COUNTIF(I$3:I$4,$A20) -> 0 | J20: =COUNTIF(J$3:J$5,$A20) -> 0 | K20: =COUNTIF(K$3:K$5,$A20) -> 0 | L20: =COUNTIF(L$3:L$6,$A20) -> 0 | M20: =COUNTIF(M$3:M$5,$A20) -> 0 | N20: =COUNTIF(N$3:N$5,$A20) -> 0 | O20: =COUNTIF(O$3:O$5,$A20) -> 0 | P20: =COUNTIF(P$3:P$5,$A20) -> 0 | Q20: =COUNTIF(Q$3:Q$6,$A20) -> 0 | R20: =COUNTIF(R$4:R$6,$A20) -> 0 | S20: =COUNTIF(S$4:S$6,$A20) -> 0 | T20: =COUNTIF(T$4:T$6,$A20) -> 0 | U20: =COUNTIF(U$4:U$5,$A20) -> 0 | V20: =COUNTIF(V$3:V$6,$A20) -> 0 | W20: =COUNTIF(W$3:W$5,$A20) -> 0 | X20: =COUNTIF(X$3:X$5,$A20) -> 0 | Y20: =COUNTIF(Y$3:Y$5,$A20) -> 0 | Z20: =COUNTIF(Z$4:Z$5,$A20) -> 0 | AA20: =COUNTIF(AA$4:AA$6,$A20) -> 0 | AB20: =COUNTIF(AB$4:AB$6,$A20) -> 0 | AC20: =COUNTIF(AC$4:AC$6,$A20) -> 0 | AD20: =COUNTIF(AD$4:AD$6,$A20) -> 0 | AE20: =COUNTIF(AE$3:AE$6,$A20) -> 0 | AF20: =COUNTIF(AF$3:AF$6,$A20) -> 0 | AG20: =COUNTIF(AG$3:AG$6,$A20) -> 0 | AH20: =COUNTIF(AH$3:AH$6,$A20) -> 0
A21: 0.75 | C21: 0.125 | D21: =COUNTIF(D$3:D$6,$A21) -> 0 | E21: =COUNTIF(E$3:E$6,$A21) -> 0 | F21: =COUNTIF(F$3:F$6,$A21) -> 0 | G21: =COUNTIF(G$3:G$6,$A21) -> 0 | H21: =COUNTIF(H$3:H$4,$A21) -> 0 | I21: =COUNTIF(I$3:I$4,$A21) -> 0 | J21: =COUNTIF(J$3:J$5,$A21) -> 0 | K21: =COUNTIF(K$3:K$5,$A21) -> 0 | L21: =COUNTIF(L$3:L$6,$A21) -> 0 | M21: =COUNTIF(M$3:M$5,$A21) -> 0 | N21: =COUNTIF(N$3:N$5,$A21) -> 0 | O21: =COUNTIF(O$3:O$5,$A21) -> 0 | P21: =COUNTIF(P$3:P$5,$A21) -> 0 | Q21: =COUNTIF(Q$3:Q$6,$A21) -> 0 | R21: =COUNTIF(R$4:R$6,$A21) -> 0 | S21: =COUNTIF(S$4:S$6,$A21) -> 0 | T21: =COUNTIF(T$4:T$6,$A21) -> 0 | U21: =COUNTIF(U$4:U$5,$A21) -> 0 | V21: =COUNTIF(V$3:V$6,$A21) -> 0 | W21: =COUNTIF(W$3:W$5,$A21) -> 0 | X21: =COUNTIF(X$3:X$5,$A21) -> 0 | Y21: =COUNTIF(Y$3:Y$5,$A21) -> 0 | Z21: =COUNTIF(Z$4:Z$5,$A21) -> 0 | AA21: =COUNTIF(AA$4:AA$6,$A21) -> 0 | AB21: =COUNTIF(AB$4:AB$6,$A21) -> 0 | AC21: =COUNTIF(AC$4:AC$6,$A21) -> 0 | AD21: =COUNTIF(AD$4:AD$6,$A21) -> 0 | AE21: =COUNTIF(AE$3:AE$6,$A21) -> 0 | AF21: =COUNTIF(AF$3:AF$6,$A21) -> 0 | AG21: =COUNTIF(AG$3:AG$6,$A21) -> 0 | AH21: =COUNTIF(AH$3:AH$6,$A21) -> 0
A22: 0.79166667 | C22: 0.16666667 | D22: =COUNTIF(D$3:D$6,$A22) -> 0 | E22: =COUNTIF(E$3:E$6,$A22) -> 0 | F22: =COUNTIF(F$3:F$6,$A22) -> 0 | G22: =COUNTIF(G$3:G$6,$A22) -> 0 | H22: =COUNTIF(H$3:H$4,$A22) -> 0 | I22: =COUNTIF(I$3:I$4,$A22) -> 0 | J22: =COUNTIF(J$3:J$5,$A22) -> 0 | K22: =COUNTIF(K$3:K$5,$A22) -> 0 | L22: =COUNTIF(L$3:L$6,$A22) -> 0 | M22: =COUNTIF(M$3:M$5,$A22) -> 0 | N22: =COUNTIF(N$3:N$5,$A22) -> 0 | O22: =COUNTIF(O$3:O$5,$A22) -> 0 | P22: =COUNTIF(P$3:P$5,$A22) -> 0 | Q22: =COUNTIF(Q$3:Q$6,$A22) -> 0 | R22: =COUNTIF(R$4:R$6,$A22) -> 0 | S22: =COUNTIF(S$4:S$6,$A22) -> 0 | T22: =COUNTIF(T$4:T$6,$A22) -> 0 | U22: =COUNTIF(U$4:U$5,$A22) -> 0 | V22: =COUNTIF(V$3:V$6,$A22) -> 0 | W22: =COUNTIF(W$3:W$5,$A22) -> 0 | X22: =COUNTIF(X$3:X$5,$A22) -> 0 | Y22: =COUNTIF(Y$3:Y$5,$A22) -> 0 | Z22: =COUNTIF(Z$4:Z$5,$A22) -> 0 | AA22: =COUNTIF(AA$4:AA$6,$A22) -> 0 | AB22: =COUNTIF(AB$4:AB$6,$A22) -> 0 | AC22: =COUNTIF(AC$4:AC$6,$A22) -> 0 | AD22: =COUNTIF(AD$4:AD$6,$A22) -> 0 | AE22: =COUNTIF(AE$3:AE$6,$A22) -> 0 | AF22: =COUNTIF(AF$3:AF$6,$A22) -> 0 | AG22: =COUNTIF(AG$3:AG$6,$A22) -> 0 | AH22: =COUNTIF(AH$3:AH$6,$A22) -> 0
A23: 0.83333333 | C23: 0.20833333 | D23: =COUNTIF(D$3:D$6,$A23) -> 0 | E23: =COUNTIF(E$3:E$6,$A23) -> 0 | F23: =COUNTIF(F$3:F$6,$A23) -> 0 | G23: =COUNTIF(G$3:G$6,$A23) -> 0 | H23: =COUNTIF(H$3:H$4,$A23) -> 0 | I23: =COUNTIF(I$3:I$4,$A23) -> 0 | J23: =COUNTIF(J$3:J$5,$A23) -> 0 | K23: =COUNTIF(K$3:K$5,$A23) -> 0 | L23: =COUNTIF(L$3:L$6,$A23) -> 0 | M23: =COUNTIF(M$3:M$5,$A23) -> 0 | N23: =COUNTIF(N$3:N$5,$A23) -> 0 | O23: =COUNTIF(O$3:O$5,$A23) -> 0 | P23: =COUNTIF(P$3:P$5,$A23) -> 0 | Q23: =COUNTIF(Q$3:Q$6,$A23) -> 0 | R23: =COUNTIF(R$4:R$6,$A23) -> 0 | S23: =COUNTIF(S$4:S$6,$A23) -> 0 | T23: =COUNTIF(T$4:T$6,$A23) -> 0 | U23: =COUNTIF(U$4:U$5,$A23) -> 0 | V23: =COUNTIF(V$3:V$6,$A23) -> 0 | W23: =COUNTIF(W$3:W$5,$A23) -> 0 | X23: =COUNTIF(X$3:X$5,$A23) -> 0 | Y23: =COUNTIF(Y$3:Y$5,$A23) -> 0 | Z23: =COUNTIF(Z$4:Z$5,$A23) -> 0 | AA23: =COUNTIF(AA$4:AA$6,$A23) -> 0 | AB23: =COUNTIF(AB$4:AB$6,$A23) -> 0 | AC23: =COUNTIF(AC$4:AC$6,$A23) -> 0 | AD23: =COUNTIF(AD$4:AD$6,$A23) -> 0 | AE23: =COUNTIF(AE$3:AE$6,$A23) -> 0 | AF23: =COUNTIF(AF$3:AF$6,$A23) -> 0 | AG23: =COUNTIF(AG$3:AG$6,$A23) -> 0 | AH23: =COUNTIF(AH$3:AH$6,$A23) -> 0
A24: 0.875 | C24: 0.25 | D24: =COUNTIF(D$3:D$6,$A24) -> 0 | E24: =COUNTIF(E$3:E$6,$A24) -> 0 | F24: =COUNTIF(F$3:F$6,$A24) -> 0 | G24: =COUNTIF(G$3:G$6,$A24) -> 0 | H24: =COUNTIF(H$3:H$4,$A24) -> 0 | I24: =COUNTIF(I$3:I$4,$A24) -> 0 | J24: =COUNTIF(J$3:J$5,$A24) -> 0 | K24: =COUNTIF(K$3:K$5,$A24) -> 0 | L24: =COUNTIF(L$3:L$6,$A24) -> 0 | M24: =COUNTIF(M$3:M$5,$A24) -> 0 | N24: =COUNTIF(N$3:N$5,$A24) -> 0 | O24: =COUNTIF(O$3:O$5,$A24) -> 0 | P24: =COUNTIF(P$3:P$5,$A24) -> 0 | Q24: =COUNTIF(Q$3:Q$6,$A24) -> 0 | R24: =COUNTIF(R$4:R$6,$A24) -> 0 | S24: =COUNTIF(S$4:S$6,$A24) -> 0 | T24: =COUNTIF(T$4:T$6,$A24) -> 0 | U24: =COUNTIF(U$4:U$5,$A24) -> 0 | V24: =COUNTIF(V$3:V$6,$A24) -> 0 | W24: =COUNTIF(W$3:W$5,$A24) -> 0 | X24: =COUNTIF(X$3:X$5,$A24) -> 0 | Y24: =COUNTIF(Y$3:Y$5,$A24) -> 0 | Z24: =COUNTIF(Z$4:Z$5,$A24) -> 0 | AA24: =COUNTIF(AA$4:AA$6,$A24) -> 0 | AB24: =COUNTIF(AB$4:AB$6,$A24) -> 0 | AC24: =COUNTIF(AC$4:AC$6,$A24) -> 0 | AD24: =COUNTIF(AD$4:AD$6,$A24) -> 0 | AE24: =COUNTIF(AE$3:AE$6,$A24) -> 0 | AF24: =COUNTIF(AF$3:AF$6,$A24) -> 0 | AG24: =COUNTIF(AG$3:AG$6,$A24) -> 0 | AH24: =COUNTIF(AH$3:AH$6,$A24) -> 0
A25: 0.91666667 | C25: 0.29166667 | D25: =COUNTIF(D$3:D$6,$A25) -> 0 | E25: =COUNTIF(E$3:E$6,$A25) -> 0 | F25: =COUNTIF(F$3:F$6,$A25) -> 0 | G25: =COUNTIF(G$3:G$6,$A25) -> 0 | H25: =COUNTIF(H$3:H$4,$A25) -> 0 | I25: =COUNTIF(I$3:I$4,$A25) -> 0 | J25: =COUNTIF(J$3:J$5,$A25) -> 0 | K25: =COUNTIF(K$3:K$5,$A25) -> 0 | L25: =COUNTIF(L$3:L$6,$A25) -> 0 | M25: =COUNTIF(M$3:M$5,$A25) -> 0 | N25: =COUNTIF(N$3:N$5,$A25) -> 0 | O25: =COUNTIF(O$3:O$5,$A25) -> 0 | P25: =COUNTIF(P$3:P$5,$A25) -> 0 | Q25: =COUNTIF(Q$3:Q$6,$A25) -> 0 | R25: =COUNTIF(R$4:R$6,$A25) -> 0 | S25: =COUNTIF(S$4:S$6,$A25) -> 0 | T25: =COUNTIF(T$4:T$6,$A25) -> 0 | U25: =COUNTIF(U$4:U$5,$A25) -> 0 | V25: =COUNTIF(V$3:V$6,$A25) -> 0 | W25: =COUNTIF(W$3:W$5,$A25) -> 0 | X25: =COUNTIF(X$3:X$5,$A25) -> 0 | Y25: =COUNTIF(Y$3:Y$5,$A25) -> 0 | Z25: =COUNTIF(Z$4:Z$5,$A25) -> 0 | AA25: =COUNTIF(AA$4:AA$6,$A25) -> 0 | AB25: =COUNTIF(AB$4:AB$6,$A25) -> 0 | AC25: =COUNTIF(AC$4:AC$6,$A25) -> 0 | AD25: =COUNTIF(AD$4:AD$6,$A25) -> 0 | AE25: =COUNTIF(AE$3:AE$6,$A25) -> 0 | AF25: =COUNTIF(AF$3:AF$6,$A25) -> 0 | AG25: =COUNTIF(AG$3:AG$6,$A25) -> 0 | AH25: =COUNTIF(AH$3:AH$6,$A25) -> 0
A26: 0.95833333 | C26: 0.33333333 | D26: =COUNTIF(D$3:D$6,$A26) -> 0 | E26: =COUNTIF(E$3:E$6,$A26) -> 0 | F26: =COUNTIF(F$3:F$6,$A26) -> 0 | G26: =COUNTIF(G$3:G$6,$A26) -> 0 | H26: =COUNTIF(H$3:H$4,$A26) -> 0 | I26: =COUNTIF(I$3:I$4,$A26) -> 0 | J26: =COUNTIF(J$3:J$5,$A26) -> 0 | K26: =COUNTIF(K$3:K$5,$A26) -> 0 | L26: =COUNTIF(L$3:L$6,$A26) -> 0 | M26: =COUNTIF(M$3:M$5,$A26) -> 0 | N26: =COUNTIF(N$3:N$5,$A26) -> 0 | O26: =COUNTIF(O$3:O$5,$A26) -> 0 | P26: =COUNTIF(P$3:P$5,$A26) -> 0 | Q26: =COUNTIF(Q$3:Q$6,$A26) -> 0 | R26: =COUNTIF(R$4:R$6,$A26) -> 0 | S26: =COUNTIF(S$4:S$6,$A26) -> 0 | T26: =COUNTIF(T$4:T$6,$A26) -> 0 | U26: =COUNTIF(U$4:U$5,$A26) -> 0 | V26: =COUNTIF(V$3:V$6,$A26) -> 0 | W26: =COUNTIF(W$3:W$5,$A26) -> 0 | X26: =COUNTIF(X$3:X$5,$A26) -> 0 | Y26: =COUNTIF(Y$3:Y$5,$A26) -> 0 | Z26: =COUNTIF(Z$4:Z$5,$A26) -> 0 | AA26: =COUNTIF(AA$4:AA$6,$A26) -> 0 | AB26: =COUNTIF(AB$4:AB$6,$A26) -> 0 | AC26: =COUNTIF(AC$4:AC$6,$A26) -> 0 | AD26: =COUNTIF(AD$4:AD$6,$A26) -> 0 | AE26: =COUNTIF(AE$3:AE$6,$A26) -> 0 | AF26: =COUNTIF(AF$3:AF$6,$A26) -> 0 | AG26: =COUNTIF(AG$3:AG$6,$A26) -> 0 | AH26: =COUNTIF(AH$3:AH$6,$A26) -> 0
... A28: 0.041666667 | C28: 0.41666667 | D28: =COUNTIF(D$3:D$6,$A28) -> 0 | E28: =COUNTIF(E$3:E$6,$A28) -> 0 | F28: =COUNTIF(F$3:F$6,$A28) -> 0 | G28: =COUNTIF(G$3:G$6,$A28) -> 0 | H28: =COUNTIF(H$3:H$4,$A28) -> 0 | I28: =COUNTIF(I$3:I$4,$A28) -> 0 | J28: =COUNTIF(J$3:J$5,$A28) -> 0 | K28: =COUNTIF(K$3:K$5,$A28) -> 0 | L28: =COUNTIF(L$3:L$6,$A28) -> 0 | M28: =COUNTIF(M$3:M$5,$A28) -> 0 | N28: =COUNTIF(N$3:N$5,$A28) -> 0 | O28: =COUNTIF(O$3:O$5,$A28) -> 0 | P28: =COUNTIF(P$3:P$5,$A28) -> 0 | Q28: =COUNTIF(Q$3:Q$6,$A28) -> 0 | R28: =COUNTIF(R$4:R$6,$A28) -> 0 | S28: =COUNTIF(S$4:S$6,$A28) -> 0 | T28: =COUNTIF(T$4:T$6,$A28) -> 0 | U28: =COUNTIF(U$4:U$5,$A28) -> 0 | V28: =COUNTIF(V$3:V$6,$A28) -> 0 | W28: =COUNTIF(W$3:W$5,$A28) -> 0 | X28: =COUNTIF(X$3:X$5,$A28) -> 0 | Y28: =COUNTIF(Y$3:Y$5,$A28) -> 0 | Z28: =COUNTIF(Z$4:Z$5,$A28) -> 0 | AA28: =COUNTIF(AA$4:AA$6,$A28) -> 0 | AB28: =COUNTIF(AB$4:AB$6,$A28) -> 0 | AC28: =COUNTIF(AC$4:AC$6,$A28) -> 0 | AD28: =COUNTIF(AD$4:AD$6,$A28) -> 0 | AE28: =COUNTIF(AE$3:AE$6,$A28) -> 0 | AF28: =COUNTIF(AF$3:AF$6,$A28) -> 0 | AG28: =COUNTIF(AG$3:AG$6,$A28) -> 0 | AH28: =COUNTIF(AH$3:AH$6,$A28) -> 0
A31: Meals
A32: Work from home
A33: Annual
A34: Public Holiday
A35: Sick
A36: Available Slot

Sheet BO
D1: Monday | E1: Tuesday | F1: Wednesday | G1: Thursday | H1: Friday | I1: Saturday | J1: Sunday | K1: Monday | L1: Tuesday | M1: Wednesday | N1: Thursday | O1: Friday | P1: Saturday | Q1: Sunday | R1: Monday | S1: Tuesday | T1: Wednesday | U1: Thursday | V1: Friday | W1: Saturday | X1: Sunday | Y1: Monday | Z1: Tuesday | AA1: Wednesday | AB1: Thursday | AC1: Friday | AD1: Saturday | AE1: Sunday | AF1: Monday | AG1: Tuesday | AH1: Wednesday
A2: Username | B2: Grade | C2: GGID | D2: 46265 | E2: 46266 | F2: 46267 | G2: 46268 | H2: 46269 | I2: 46270 | J2: 46271 | K2: 46272 | L2: 46273 | M2: 46274 | N2: 46275 | O2: 46276 | P2: 46277 | Q2: 46278 | R2: 46279 | S2: 46280 | T2: 46281 | U2: 46282 | V2: 46283 | W2: 46284 | X2: 46285 | Y2: 46286 | Z2: 46287 | AA2: 46288 | AB2: 46289 | AC2: 46290 | AD2: 46291 | AE2: 46292 | AF2: 46293 | AG2: 46294 | AH2: 46295 | AO2: 0.29166667 | AP2: 0.33333333 | AQ2: 0.375 | AR2: 0.41666667 | AS2: 0.45833333 | AT2: 0.5 | AU2: 0.54166667 | AV2: 0.58333333 | AW2: 0.625 | AX2: 0.66666667 | AY2: 0.70833333 | AZ2: 0.75 | BA2: 0.79166667 | BB2: 0.83333333 | BC2: 0.875 | BD2: 0.91666667 | BE2: 0.95833333 | BF2: 1 | BI2: WD | BJ2: OFF | BK2: Annual | BL2: Compensation
A3: Mohamed Abdellatif | B3: KM | C3: 30001801 | D3: Annual | E3: Annual | F3: Annual | G3: Annual | H3: Annual | I3: OFF | J3: OFF | K3: 0.41666667 | L3: 0.41666667 | M3: 0.41666667 | N3: 0.41666667 | O3: 0.41666667 | P3: OFF | Q3: OFF | R3: 0.41666667 | S3: 0.41666667 | T3: 0.41666667 | U3: 0.41666667 | V3: 0.41666667 | W3: OFF | X3: OFF | Y3: 0.41666667 | Z3: 0.41666667 | AA3: 0.41666667 | AB3: 0.41666667 | AC3: 0.41666667 | AD3: OFF | AE3: OFF | AF3: 0.41666667 | AG3: 0.41666667 | AH3: 0.41666667 | AO3: =COUNTIF($D3:$AG3,AO$2) -> 0 | AP3: =COUNTIF($D3:$AG3,AP$2) -> 0 | AQ3: =COUNTIF($D3:$AG3,AQ$2) -> 0 | AR3: =COUNTIF($D3:$AG3,AR$2) -> 17 | AS3: =COUNTIF($D3:$AG3,AS$2) -> 0 | AT3: =COUNTIF($D3:$AG3,AT$2) -> 0 | AU3: =COUNTIF($D3:$AG3,AU$2) -> 0 | AV3: =COUNTIF($D3:$AG3,AV$2) -> 0 | ... BF3: =COUNTIF($D3:$AG3,BF$2) -> 0 | BI3: =SUM(AO3:BG3) -> 17 | BJ3: =COUNTIF(D3:AG3,$BJ$2) -> 8 | BK3: =COUNTIF(D3:AG3,$BK$2) -> 5 | BL3: =COUNTIF(D3:AG3,$BL$2) -> 0
A4: Wessam Ahmed | B4: IM CO | C4: 1847229 | D4: 0.375 | E4: 0.375 | F4: 0.375 | G4: 0.375 | H4: 0.375 | I4: OFF | J4: OFF | K4: 0.375 | L4: Sick | M4: Sick | N4: Compensation | O4: Compensation | P4: OFF | Q4: OFF | R4: 0.375 | S4: 0.375 | T4: 0.375 | U4: 0.375 | V4: 0.375 | W4: OFF | X4: OFF | Y4: 0.375 | Z4: 0.375 | AA4: 0.375 | AB4: 0.375 | AC4: 0.375 | AD4: OFF | AE4: OFF | AF4: 0.375 | AG4: 0.375 | AH4: 0.375 | AO4: =COUNTIF($D4:$AG4,AO$2) -> 0 | AP4: =COUNTIF($D4:$AG4,AP$2) -> 0 | AQ4: =COUNTIF($D4:$AG4,AQ$2) -> 18 | AR4: =COUNTIF($D4:$AG4,AR$2) -> 0 | AS4: =COUNTIF($D4:$AG4,AS$2) -> 0 | AT4: =COUNTIF($D4:$AG4,AT$2) -> 0 | AU4: =COUNTIF($D4:$AG4,AU$2) -> 0 | AV4: =COUNTIF($D4:$AG4,AV$2) -> 0 | ... BF4: =COUNTIF($D4:$AG4,BF$2) -> 0 | BI4: =SUM(AO4:BG4) -> 18 | BJ4: =COUNTIF(D4:AG4,$BJ$2) -> 8 | BK4: =COUNTIF(D4:AG4,$BK$2) -> 0 | BL4: =COUNTIF(D4:AG4,$BL$2) -> 2
A5: Reham Baghdady | B5: IM | C5: 1842172 | D5: Compensation | E5: 0.375 | F5: 0.375 | G5: 0.375 | H5: 0.375 | I5: OFF | J5: OFF | K5: 0.375 | L5: 0.375 | M5: 0.375 | N5: 0.375 | O5: 0.375 | P5: OFF | Q5: OFF | R5: 0.375 | S5: 0.375 | T5: 0.375 | U5: 0.375 | V5: 0.375 | W5: OFF | X5: OFF | Y5: 0.375 | Z5: 0.375 | AA5: 0.375 | AB5: 0.375 | AC5: 0.375 | AD5: OFF | AE5: OFF | AF5: 0.375 | AG5: 0.375 | AH5: 0.375 | AO5: =COUNTIF($D5:$AG5,AO$2) -> 0 | AP5: =COUNTIF($D5:$AG5,AP$2) -> 0 | AQ5: =COUNTIF($D5:$AG5,AQ$2) -> 21 | AR5: =COUNTIF($D5:$AG5,AR$2) -> 0 | AS5: =COUNTIF($D5:$AG5,AS$2) -> 0 | AT5: =COUNTIF($D5:$AG5,AT$2) -> 0 | AU5: =COUNTIF($D5:$AG5,AU$2) -> 0 | AV5: =COUNTIF($D5:$AG5,AV$2) -> 0 | ... BF5: =COUNTIF($D5:$AG5,BF$2) -> 0 | BI5: =SUM(AO5:BG5) -> 21 | BJ5: =COUNTIF(D5:AG5,$BJ$2) -> 8 | BK5: =COUNTIF(D5:AG5,$BK$2) -> 0 | BL5: =COUNTIF(D5:AG5,$BL$2) -> 1
A6: Maha Dahshan | B6: PM | C6: 30031810 | D6: 0.41666667 | E6: 0.41666667 | F6: 0.41666667 | G6: 0.41666667 | H6: 0.41666667 | I6: OFF | J6: OFF | K6: 0.41666667 | L6: 0.41666667 | M6: 0.41666667 | N6: 0.41666667 | O6: Compensation | P6: OFF | Q6: OFF | R6: 0.41666667 | S6: 0.41666667 | T6: 0.41666667 | U6: 0.41666667 | V6: 0.41666667 | W6: OFF | X6: OFF | Y6: 0.41666667 | Z6: 0.41666667 | AA6: 0.41666667 | AB6: 0.41666667 | AC6: 0.41666667 | AD6: OFF | AE6: OFF | AF6: 0.41666667 | AG6: 0.41666667 | AH6: 0.41666667 | AO6: =COUNTIF($D6:$AG6,AO$2) -> 0 | AP6: =COUNTIF($D6:$AG6,AP$2) -> 0 | AQ6: =COUNTIF($D6:$AG6,AQ$2) -> 0 | AR6: =COUNTIF($D6:$AG6,AR$2) -> 21 | AS6: =COUNTIF($D6:$AG6,AS$2) -> 0 | AT6: =COUNTIF($D6:$AG6,AT$2) -> 0 | AU6: =COUNTIF($D6:$AG6,AU$2) -> 0 | AV6: =COUNTIF($D6:$AG6,AV$2) -> 0 | ... BF6: =COUNTIF($D6:$AG6,BF$2) -> 0 | BI6: =SUM(AO6:BG6) -> 21 | BJ6: =COUNTIF(D6:AG6,$BJ$2) -> 8 | BK6: =COUNTIF(D6:AG6,$BK$2) -> 0 | BL6: =COUNTIF(D6:AG6,$BL$2) -> 1
A7: Omar Khodir | B7: TM | C7: 30001994 | D7: 0.41666667 | E7: 0.41666667 | F7: 0.41666667 | G7: 0.41666667 | H7: 0.41666667 | I7: OFF | J7: OFF | K7: 0.41666667 | L7: 0.41666667 | M7: 0.41666667 | N7: 0.41666667 | O7: 0.41666667 | P7: OFF | Q7: OFF | R7: 0.41666667 | S7: 0.41666667 | T7: 0.41666667 | U7: 0.41666667 | V7: 0.41666667 | W7: OFF | X7: OFF | Y7: Annual | Z7: Annual | AA7: Annual | AB7: Annual | AC7: Annual | AD7: OFF | AE7: OFF | AF7: 0.41666667 | AG7: 0.41666667 | AH7: 0.41666667 | AO7: =COUNTIF($D7:$AG7,AO$2) -> 0 | AP7: =COUNTIF($D7:$AG7,AP$2) -> 0 | AQ7: =COUNTIF($D7:$AG7,AQ$2) -> 0 | AR7: =COUNTIF($D7:$AG7,AR$2) -> 17 | AS7: =COUNTIF($D7:$AG7,AS$2) -> 0 | AT7: =COUNTIF($D7:$AG7,AT$2) -> 0 | AU7: =COUNTIF($D7:$AG7,AU$2) -> 0 | AV7: =COUNTIF($D7:$AG7,AV$2) -> 0 | ... BF7: =COUNTIF($D7:$AG7,BF$2) -> 0 | BI7: =SUM(AO7:BG7) -> 17 | BJ7: =COUNTIF(D7:AG7,$BJ$2) -> 8 | BK7: =COUNTIF(D7:AG7,$BK$2) -> 5 | BL7: =COUNTIF(D7:AG7,$BL$2) -> 0
W8: Eid Vacation
A9: Meals
A10: Work from home
A11: Annual
A12: Public Holiday
A13: Training
A14: Sick
A15: Available Slot

Sheet WFH
A1: Username | B1: Grade | C1: ='L1'!#REF! -> #REF! | D1: ='L1'!#REF! -> #REF! | E1: ='L1'!#REF! -> #REF! | F1: ='L1'!#REF! -> #REF! | G1: ='L1'!#REF! -> #REF! | H1: ='L1'!#REF! -> #REF! | I1: ='L1'!#REF! -> #REF! | J1: ='L1'!#REF! -> #REF! | ... M1: ='L1'!#REF! -> #REF! | N1: ='L1'!D1 -> Monday | O1: ='L1'!E1 -> Tuesday | P1: ='L1'!F1 -> Wednesday | Q1: ='L1'!G1 -> Thursday | R1: ='L1'!H1 -> Friday | S1: ='L1'!I1 -> Saturday | T1: ='L1'!J1 -> Sunday | U1: ='L1'!K1 -> Monday | ... AF1: ='L1'!V1 -> Friday | AG1: ='L1'!#REF! -> #REF!
A2: ='L1'!A3 -> Amr Abdelwahab | B2: L1 | C2: ='L1'!#REF! -> #REF! | D2: ='L1'!#REF! -> #REF! | E2: ='L1'!#REF! -> #REF! | F2: ='L1'!#REF! -> #REF! | G2: ='L1'!#REF! -> #REF! | H2: ='L1'!#REF! -> #REF! | I2: ='L1'!#REF! -> #REF! | J2: ='L1'!#REF! -> #REF! | ... N2: ='L1'!#REF! -> #REF! | O2: ='L1'!K3 -> Annual | P2: ='L1'!#REF! -> #REF! | Q2: ='L1'!#REF! -> #REF! | R2: ='L1'!#REF! -> #REF! | S2: ='L1'!#REF! -> #REF! | T2: ='L1'!#REF! -> #REF! | U2: ='L1'!Q3 -> OFF
A3: ='L1'!#REF! -> #REF! | B3: L1 | C3: ='L1'!#REF! -> #REF! | D3: ='L1'!#REF! -> #REF! | E3: ='L1'!#REF! -> #REF! | F3: ='L1'!#REF! -> #REF! | G3: ='L1'!#REF! -> #REF! | H3: ='L1'!#REF! -> #REF! | I3: ='L1'!D4 -> Sick | J3: ='L1'!#REF! -> #REF! | K3: ='L1'!#REF! -> #REF! | L3: ='L1'!#REF! -> #REF! | M3: ='L1'!#REF! -> #REF! | N3: ='L1'!#REF! -> #REF! | O3: ='L1'!K4 -> 0.375 | P3: ='L1'!#REF! -> #REF! | Q3: ='L1'!#REF! -> #REF! | R3: ='L1'!#REF! -> #REF! | S3: ='L1'!#REF! -> #REF! | T3: ='L1'!#REF! -> #REF! | U3: ='L1'!#REF! -> #REF!
A4: ='L1'!#REF! -> #REF! | B4: L1 | C4: ='L1'!#REF! -> #REF! | D4: ='L1'!#REF! -> #REF! | E4: ='L1'!#REF! -> #REF! | F4: ='L1'!#REF! -> #REF! | G4: ='L1'!#REF! -> #REF! | H4: ='L1'!#REF! -> #REF! | I4: ='L1'!D3 -> 0.45833333 | J4: ='L1'!#REF! -> #REF! | K4: ='L1'!#REF! -> #REF! | L4: ='L1'!#REF! -> #REF! | M4: ='L1'!#REF! -> #REF! | N4: ='L1'!#REF! -> #REF! | O4: ='L1'!#REF! -> #REF! | P4: ='L1'!#REF! -> #REF! | Q4: ='L1'!#REF! -> #REF! | ... U4: ='L1'!#REF! -> #REF!
A5: ='L1'!#REF! -> #REF! | B5: L1 | C5: ='L1'!#REF! -> #REF! | D5: ='L1'!#REF! -> #REF! | E5: ='L1'!#REF! -> #REF! | F5: ='L1'!#REF! -> #REF! | G5: ='L1'!#REF! -> #REF! | H5: ='L1'!#REF! -> #REF! | I5: ='L1'!D5 -> 0.58333333 | J5: ='L1'!#REF! -> #REF! | K5: ='L1'!#REF! -> #REF! | L5: ='L1'!#REF! -> #REF! | M5: ='L1'!#REF! -> #REF! | N5: ='L1'!#REF! -> #REF! | O5: ='L1'!K5 -> 0.29166667 | P5: ='L1'!#REF! -> #REF! | Q5: ='L1'!#REF! -> #REF! | R5: ='L1'!#REF! -> #REF! | S5: ='L1'!#REF! -> #REF! | T5: ='L1'!#REF! -> #REF! | U5: ='L1'!Q5 -> OFF
A6: ='L1'!#REF! -> #REF! | B6: L1 | C6: ='L1'!#REF! -> #REF! | D6: ='L1'!#REF! -> #REF! | E6: ='L1'!#REF! -> #REF! | F6: ='L1'!#REF! -> #REF! | G6: ='L1'!#REF! -> #REF! | H6: ='L1'!#REF! -> #REF! | I6: ='L1'!#REF! -> #REF! | J6: ='L1'!#REF! -> #REF! | ... U6: ='L1'!#REF! -> #REF!
A7: ='L1'!#REF! -> #REF! | B7: L1 | C7: ='L1'!#REF! -> #REF! | D7: ='L1'!#REF! -> #REF! | E7: ='L1'!#REF! -> #REF! | F7: ='L1'!#REF! -> #REF! | G7: ='L1'!#REF! -> #REF! | H7: ='L1'!#REF! -> #REF! | I7: ='L1'!#REF! -> #REF! | J7: ='L1'!#REF! -> #REF! | ... U7: ='L1'!#REF! -> #REF!
A8: ='L1'!#REF! -> #REF! | B8: L1 | C8: ='L1'!#REF! -> #REF! | D8: ='L1'!#REF! -> #REF! | E8: ='L1'!#REF! -> #REF! | F8: ='L1'!#REF! -> #REF! | G8: ='L1'!#REF! -> #REF! | H8: ='L1'!#REF! -> #REF! | I8: ='L1'!#REF! -> #REF! | J8: ='L1'!#REF! -> #REF! | ... U8: ='L1'!#REF! -> #REF!
A9: ='L1'!#REF! -> #REF! | B9: L1 | C9: ='L1'!#REF! -> #REF! | D9: ='L1'!#REF! -> #REF! | E9: ='L1'!#REF! -> #REF! | F9: ='L1'!#REF! -> #REF! | G9: ='L1'!#REF! -> #REF! | H9: ='L1'!#REF! -> #REF! | I9: ='L1'!#REF! -> #REF! | J9: ='L1'!#REF! -> #REF! | ... U9: ='L1'!#REF! -> #REF!
A10: ='L2'!A4 -> Mohamed Aly | B10: L2 | C10: ='L2'!#REF! -> #REF! | D10: ='L2'!E3 -> 0.33333333 | E10: ='L2'!F3 -> 0.33333333 | F10: ='L2'!#REF! -> #REF! | G10: ='L2'!#REF! -> #REF! | H10: ='L2'!#REF! -> #REF! | I10: ='L2'!#REF! -> #REF! | J10: ='L2'!N6 -> 0.33333333 | K10: ='L2'!L3 -> 0.41666667 | L10: ='L2'!M6 -> 0.33333333 | M10: ='L2'!#REF! -> #REF! | N10: ='L2'!#REF! -> #REF! | O10: ='L2'!#REF! -> #REF! | P10: ='L2'!#REF! -> #REF! | Q10: ='L2'!R4 -> 0.41666667 | R10: ='L2'!S4 -> Sick | S10: ='L2'!T4 -> Sick | T10: ='L2'!#REF! -> #REF! | U10: ='L2'!#REF! -> #REF!
A11: ='L2'!A5 -> Amr Elsherbiny | B11: L2 | C11: ='L2'!#REF! -> #REF! | D11: ='L2'!E6 -> 0.41666667 | E11: ='L2'!F6 -> 0.41666667 | F11: ='L2'!#REF! -> #REF! | G11: ='L2'!#REF! -> #REF! | H11: ='L2'!#REF! -> #REF! | I11: ='L2'!G6 -> 0.41666667 | J11: ='L2'!N4 -> 0.33333333 | K11: ='L2'!L6 -> 0.33333333 | L11: ='L2'!M4 -> 0.33333333 | M11: ='L2'!#REF! -> #REF! | N11: ='L2'!#REF! -> #REF! | O11: ='L2'!#REF! -> #REF! | P11: ='L2'!#REF! -> #REF! | Q11: ='L2'!#REF! -> #REF! | R11: ='L2'!#REF! -> #REF! | S11: ='L2'!T5 -> 0.58333333 | T11: ='L2'!#REF! -> #REF! | U11: ='L2'!#REF! -> #REF!
